2025-08-15 19:03:50,613 - __main__ - ERROR - main:main:68
Message: Application crashed: cannot use geometry manager pack inside .!frame.!frame which already has slaves managed by grid
Exception: (<class '_tkinter.TclError'>, TclError('cannot use geometry manager pack inside .!frame.!frame which already has slaves managed by grid'), <traceback object at 0x00000253D245C400>)
---
Traceback (most recent call last):
  File "C:\Users\nolan\personal\personal-projects\Nabu\main.py", line 59, in main
    app = TutorApplication()
  File "C:\Users\nolan\personal\personal-projects\Nabu\core\application.py", line 49, in __init__
    self._initialize_ui()
  File "C:\Users\nolan\personal\personal-projects\Nabu\core\application.py", line 80, in _initialize_ui
    self.dashboard_frame = DashboardFrame(
  File "C:\Users\nolan\personal\personal-projects\Nabu\ui\dashboard.py", line 30, in __init__
    self._setup_layout()
  File "C:\Users\nolan\personal\personal-projects\Nabu\ui\dashboard.py", line 119, in _setup_layout
    self.start_button.pack(side=tk.LEFT, padx=self.theme.SPACING['sm'])
  File "C:\Users\nolan\Anaconda3\lib\tkinter\__init__.py", line 2396, in pack_configure
    self.tk.call(
_tkinter.TclError: cannot use geometry manager pack inside .!frame.!frame which already has slaves managed by grid
2025-08-15 19:04:28,324 - data.database - ERROR - database:get_connection:47
Message: Database operation failed: UNIQUE constraint failed: settings.key
Exception: (<class 'sqlite3.IntegrityError'>, IntegrityError('UNIQUE constraint failed: settings.key'), <traceback object at 0x000001B189CC4CC0>)
---
Traceback (most recent call last):
  File "C:\Users\nolan\personal\personal-projects\Nabu\data\database.py", line 43, in get_connection
    yield conn
  File "C:\Users\nolan\personal\personal-projects\Nabu\data\database.py", line 130, in insert
    cursor = conn.execute(query, tuple(data.values()))
sqlite3.IntegrityError: UNIQUE constraint failed: settings.key
2025-08-15 19:04:28,332 - data.database - ERROR - database:get_connection:47
Message: Database operation failed: UNIQUE constraint failed: settings.key
Exception: (<class 'sqlite3.IntegrityError'>, IntegrityError('UNIQUE constraint failed: settings.key'), <traceback object at 0x000001B189CC4D00>)
---
Traceback (most recent call last):
  File "C:\Users\nolan\personal\personal-projects\Nabu\data\database.py", line 43, in get_connection
    yield conn
  File "C:\Users\nolan\personal\personal-projects\Nabu\data\database.py", line 130, in insert
    cursor = conn.execute(query, tuple(data.values()))
sqlite3.IntegrityError: UNIQUE constraint failed: settings.key
2025-08-15 19:04:28,336 - data.database - ERROR - database:get_connection:47
Message: Database operation failed: UNIQUE constraint failed: settings.key
Exception: (<class 'sqlite3.IntegrityError'>, IntegrityError('UNIQUE constraint failed: settings.key'), <traceback object at 0x000001B189CC4CC0>)
---
Traceback (most recent call last):
  File "C:\Users\nolan\personal\personal-projects\Nabu\data\database.py", line 43, in get_connection
    yield conn
  File "C:\Users\nolan\personal\personal-projects\Nabu\data\database.py", line 130, in insert
    cursor = conn.execute(query, tuple(data.values()))
sqlite3.IntegrityError: UNIQUE constraint failed: settings.key
2025-08-15 19:04:28,345 - data.database - ERROR - database:get_connection:47
Message: Database operation failed: UNIQUE constraint failed: settings.key
Exception: (<class 'sqlite3.IntegrityError'>, IntegrityError('UNIQUE constraint failed: settings.key'), <traceback object at 0x000001B189CC4D00>)
---
Traceback (most recent call last):
  File "C:\Users\nolan\personal\personal-projects\Nabu\data\database.py", line 43, in get_connection
    yield conn
  File "C:\Users\nolan\personal\personal-projects\Nabu\data\database.py", line 130, in insert
    cursor = conn.execute(query, tuple(data.values()))
sqlite3.IntegrityError: UNIQUE constraint failed: settings.key
2025-08-15 19:04:28,354 - data.database - ERROR - database:get_connection:47
Message: Database operation failed: UNIQUE constraint failed: settings.key
Exception: (<class 'sqlite3.IntegrityError'>, IntegrityError('UNIQUE constraint failed: settings.key'), <traceback object at 0x000001B189CC4CC0>)
---
Traceback (most recent call last):
  File "C:\Users\nolan\personal\personal-projects\Nabu\data\database.py", line 43, in get_connection
    yield conn
  File "C:\Users\nolan\personal\personal-projects\Nabu\data\database.py", line 130, in insert
    cursor = conn.execute(query, tuple(data.values()))
sqlite3.IntegrityError: UNIQUE constraint failed: settings.key
2025-08-15 19:04:28,360 - data.database - ERROR - database:get_connection:47
Message: Database operation failed: UNIQUE constraint failed: settings.key
Exception: (<class 'sqlite3.IntegrityError'>, IntegrityError('UNIQUE constraint failed: settings.key'), <traceback object at 0x000001B189CC4D00>)
---
Traceback (most recent call last):
  File "C:\Users\nolan\personal\personal-projects\Nabu\data\database.py", line 43, in get_connection
    yield conn
  File "C:\Users\nolan\personal\personal-projects\Nabu\data\database.py", line 130, in insert
    cursor = conn.execute(query, tuple(data.values()))
sqlite3.IntegrityError: UNIQUE constraint failed: settings.key
2025-08-15 19:04:28,365 - data.database - ERROR - database:get_connection:47
Message: Database operation failed: UNIQUE constraint failed: settings.key
Exception: (<class 'sqlite3.IntegrityError'>, IntegrityError('UNIQUE constraint failed: settings.key'), <traceback object at 0x000001B189CC4CC0>)
---
Traceback (most recent call last):
  File "C:\Users\nolan\personal\personal-projects\Nabu\data\database.py", line 43, in get_connection
    yield conn
  File "C:\Users\nolan\personal\personal-projects\Nabu\data\database.py", line 130, in insert
    cursor = conn.execute(query, tuple(data.values()))
sqlite3.IntegrityError: UNIQUE constraint failed: settings.key
2025-08-15 19:04:28,371 - data.database - ERROR - database:get_connection:47
Message: Database operation failed: UNIQUE constraint failed: settings.key
Exception: (<class 'sqlite3.IntegrityError'>, IntegrityError('UNIQUE constraint failed: settings.key'), <traceback object at 0x000001B189CC4D00>)
---
Traceback (most recent call last):
  File "C:\Users\nolan\personal\personal-projects\Nabu\data\database.py", line 43, in get_connection
    yield conn
  File "C:\Users\nolan\personal\personal-projects\Nabu\data\database.py", line 130, in insert
    cursor = conn.execute(query, tuple(data.values()))
sqlite3.IntegrityError: UNIQUE constraint failed: settings.key
2025-08-15 19:04:28,381 - data.database - ERROR - database:get_connection:47
Message: Database operation failed: UNIQUE constraint failed: settings.key
Exception: (<class 'sqlite3.IntegrityError'>, IntegrityError('UNIQUE constraint failed: settings.key'), <traceback object at 0x000001B189CC4CC0>)
---
Traceback (most recent call last):
  File "C:\Users\nolan\personal\personal-projects\Nabu\data\database.py", line 43, in get_connection
    yield conn
  File "C:\Users\nolan\personal\personal-projects\Nabu\data\database.py", line 130, in insert
    cursor = conn.execute(query, tuple(data.values()))
sqlite3.IntegrityError: UNIQUE constraint failed: settings.key
2025-08-15 19:04:28,386 - data.database - ERROR - database:get_connection:47
Message: Database operation failed: UNIQUE constraint failed: settings.key
Exception: (<class 'sqlite3.IntegrityError'>, IntegrityError('UNIQUE constraint failed: settings.key'), <traceback object at 0x000001B189CC4D00>)
---
Traceback (most recent call last):
  File "C:\Users\nolan\personal\personal-projects\Nabu\data\database.py", line 43, in get_connection
    yield conn
  File "C:\Users\nolan\personal\personal-projects\Nabu\data\database.py", line 130, in insert
    cursor = conn.execute(query, tuple(data.values()))
sqlite3.IntegrityError: UNIQUE constraint failed: settings.key
2025-08-15 19:04:28,404 - data.database - ERROR - database:get_connection:47
Message: Database operation failed: UNIQUE constraint failed: vocabulary.word, vocabulary.language
Exception: (<class 'sqlite3.IntegrityError'>, IntegrityError('UNIQUE constraint failed: vocabulary.word, vocabulary.language'), <traceback object at 0x000001B189CC4CC0>)
---
Traceback (most recent call last):
  File "C:\Users\nolan\personal\personal-projects\Nabu\data\database.py", line 43, in get_connection
    yield conn
  File "C:\Users\nolan\personal\personal-projects\Nabu\data\database.py", line 130, in insert
    cursor = conn.execute(query, tuple(data.values()))
sqlite3.IntegrityError: UNIQUE constraint failed: vocabulary.word, vocabulary.language
2025-08-15 19:04:28,412 - data.database - ERROR - database:get_connection:47
Message: Database operation failed: UNIQUE constraint failed: vocabulary.word, vocabulary.language
Exception: (<class 'sqlite3.IntegrityError'>, IntegrityError('UNIQUE constraint failed: vocabulary.word, vocabulary.language'), <traceback object at 0x000001B189CC4D00>)
---
Traceback (most recent call last):
  File "C:\Users\nolan\personal\personal-projects\Nabu\data\database.py", line 43, in get_connection
    yield conn
  File "C:\Users\nolan\personal\personal-projects\Nabu\data\database.py", line 130, in insert
    cursor = conn.execute(query, tuple(data.values()))
sqlite3.IntegrityError: UNIQUE constraint failed: vocabulary.word, vocabulary.language
2025-08-15 19:16:45,646 - data.database - ERROR - database:get_connection:47
Message: Database operation failed: UNIQUE constraint failed: settings.key
Exception: (<class 'sqlite3.IntegrityError'>, IntegrityError('UNIQUE constraint failed: settings.key'), <traceback object at 0x0000024745AFD2C0>)
---
Traceback (most recent call last):
  File "C:\Users\nolan\personal\personal-projects\Nabu\data\database.py", line 43, in get_connection
    yield conn
  File "C:\Users\nolan\personal\personal-projects\Nabu\data\database.py", line 130, in insert
    cursor = conn.execute(query, tuple(data.values()))
sqlite3.IntegrityError: UNIQUE constraint failed: settings.key
2025-08-15 19:16:45,654 - data.database - ERROR - database:get_connection:47
Message: Database operation failed: UNIQUE constraint failed: settings.key
Exception: (<class 'sqlite3.IntegrityError'>, IntegrityError('UNIQUE constraint failed: settings.key'), <traceback object at 0x0000024745AFD380>)
---
Traceback (most recent call last):
  File "C:\Users\nolan\personal\personal-projects\Nabu\data\database.py", line 43, in get_connection
    yield conn
  File "C:\Users\nolan\personal\personal-projects\Nabu\data\database.py", line 130, in insert
    cursor = conn.execute(query, tuple(data.values()))
sqlite3.IntegrityError: UNIQUE constraint failed: settings.key
2025-08-15 19:16:45,659 - data.database - ERROR - database:get_connection:47
Message: Database operation failed: UNIQUE constraint failed: settings.key
Exception: (<class 'sqlite3.IntegrityError'>, IntegrityError('UNIQUE constraint failed: settings.key'), <traceback object at 0x0000024745AFD2C0>)
---
Traceback (most recent call last):
  File "C:\Users\nolan\personal\personal-projects\Nabu\data\database.py", line 43, in get_connection
    yield conn
  File "C:\Users\nolan\personal\personal-projects\Nabu\data\database.py", line 130, in insert
    cursor = conn.execute(query, tuple(data.values()))
sqlite3.IntegrityError: UNIQUE constraint failed: settings.key
2025-08-15 19:16:45,668 - data.database - ERROR - database:get_connection:47
Message: Database operation failed: UNIQUE constraint failed: settings.key
Exception: (<class 'sqlite3.IntegrityError'>, IntegrityError('UNIQUE constraint failed: settings.key'), <traceback object at 0x0000024745AFD380>)
---
Traceback (most recent call last):
  File "C:\Users\nolan\personal\personal-projects\Nabu\data\database.py", line 43, in get_connection
    yield conn
  File "C:\Users\nolan\personal\personal-projects\Nabu\data\database.py", line 130, in insert
    cursor = conn.execute(query, tuple(data.values()))
sqlite3.IntegrityError: UNIQUE constraint failed: settings.key
2025-08-15 19:16:45,674 - data.database - ERROR - database:get_connection:47
Message: Database operation failed: UNIQUE constraint failed: settings.key
Exception: (<class 'sqlite3.IntegrityError'>, IntegrityError('UNIQUE constraint failed: settings.key'), <traceback object at 0x0000024745AFD2C0>)
---
Traceback (most recent call last):
  File "C:\Users\nolan\personal\personal-projects\Nabu\data\database.py", line 43, in get_connection
    yield conn
  File "C:\Users\nolan\personal\personal-projects\Nabu\data\database.py", line 130, in insert
    cursor = conn.execute(query, tuple(data.values()))
sqlite3.IntegrityError: UNIQUE constraint failed: settings.key
2025-08-15 19:16:45,678 - data.database - ERROR - database:get_connection:47
Message: Database operation failed: UNIQUE constraint failed: settings.key
Exception: (<class 'sqlite3.IntegrityError'>, IntegrityError('UNIQUE constraint failed: settings.key'), <traceback object at 0x0000024745AFD380>)
---
Traceback (most recent call last):
  File "C:\Users\nolan\personal\personal-projects\Nabu\data\database.py", line 43, in get_connection
    yield conn
  File "C:\Users\nolan\personal\personal-projects\Nabu\data\database.py", line 130, in insert
    cursor = conn.execute(query, tuple(data.values()))
sqlite3.IntegrityError: UNIQUE constraint failed: settings.key
2025-08-15 19:16:45,683 - data.database - ERROR - database:get_connection:47
Message: Database operation failed: UNIQUE constraint failed: settings.key
Exception: (<class 'sqlite3.IntegrityError'>, IntegrityError('UNIQUE constraint failed: settings.key'), <traceback object at 0x0000024745AFD2C0>)
---
Traceback (most recent call last):
  File "C:\Users\nolan\personal\personal-projects\Nabu\data\database.py", line 43, in get_connection
    yield conn
  File "C:\Users\nolan\personal\personal-projects\Nabu\data\database.py", line 130, in insert
    cursor = conn.execute(query, tuple(data.values()))
sqlite3.IntegrityError: UNIQUE constraint failed: settings.key
2025-08-15 19:16:45,690 - data.database - ERROR - database:get_connection:47
Message: Database operation failed: UNIQUE constraint failed: settings.key
Exception: (<class 'sqlite3.IntegrityError'>, IntegrityError('UNIQUE constraint failed: settings.key'), <traceback object at 0x0000024745AFD380>)
---
Traceback (most recent call last):
  File "C:\Users\nolan\personal\personal-projects\Nabu\data\database.py", line 43, in get_connection
    yield conn
  File "C:\Users\nolan\personal\personal-projects\Nabu\data\database.py", line 130, in insert
    cursor = conn.execute(query, tuple(data.values()))
sqlite3.IntegrityError: UNIQUE constraint failed: settings.key
2025-08-15 19:16:45,701 - data.database - ERROR - database:get_connection:47
Message: Database operation failed: UNIQUE constraint failed: settings.key
Exception: (<class 'sqlite3.IntegrityError'>, IntegrityError('UNIQUE constraint failed: settings.key'), <traceback object at 0x0000024745AFD2C0>)
---
Traceback (most recent call last):
  File "C:\Users\nolan\personal\personal-projects\Nabu\data\database.py", line 43, in get_connection
    yield conn
  File "C:\Users\nolan\personal\personal-projects\Nabu\data\database.py", line 130, in insert
    cursor = conn.execute(query, tuple(data.values()))
sqlite3.IntegrityError: UNIQUE constraint failed: settings.key
2025-08-15 19:16:45,713 - data.database - ERROR - database:get_connection:47
Message: Database operation failed: UNIQUE constraint failed: settings.key
Exception: (<class 'sqlite3.IntegrityError'>, IntegrityError('UNIQUE constraint failed: settings.key'), <traceback object at 0x0000024745AFD380>)
---
Traceback (most recent call last):
  File "C:\Users\nolan\personal\personal-projects\Nabu\data\database.py", line 43, in get_connection
    yield conn
  File "C:\Users\nolan\personal\personal-projects\Nabu\data\database.py", line 130, in insert
    cursor = conn.execute(query, tuple(data.values()))
sqlite3.IntegrityError: UNIQUE constraint failed: settings.key
2025-08-15 19:16:45,734 - data.database - ERROR - database:get_connection:47
Message: Database operation failed: UNIQUE constraint failed: vocabulary.word, vocabulary.language
Exception: (<class 'sqlite3.IntegrityError'>, IntegrityError('UNIQUE constraint failed: vocabulary.word, vocabulary.language'), <traceback object at 0x0000024745AFD2C0>)
---
Traceback (most recent call last):
  File "C:\Users\nolan\personal\personal-projects\Nabu\data\database.py", line 43, in get_connection
    yield conn
  File "C:\Users\nolan\personal\personal-projects\Nabu\data\database.py", line 130, in insert
    cursor = conn.execute(query, tuple(data.values()))
sqlite3.IntegrityError: UNIQUE constraint failed: vocabulary.word, vocabulary.language
2025-08-15 19:16:45,741 - data.database - ERROR - database:get_connection:47
Message: Database operation failed: UNIQUE constraint failed: vocabulary.word, vocabulary.language
Exception: (<class 'sqlite3.IntegrityError'>, IntegrityError('UNIQUE constraint failed: vocabulary.word, vocabulary.language'), <traceback object at 0x0000024745AFD380>)
---
Traceback (most recent call last):
  File "C:\Users\nolan\personal\personal-projects\Nabu\data\database.py", line 43, in get_connection
    yield conn
  File "C:\Users\nolan\personal\personal-projects\Nabu\data\database.py", line 130, in insert
    cursor = conn.execute(query, tuple(data.values()))
sqlite3.IntegrityError: UNIQUE constraint failed: vocabulary.word, vocabulary.language
2025-08-15 19:16:46,402 - core.application - ERROR - application:_initialize_ai_agent:119
Message: Failed to initialize AI agent: __init__() missing 1 required positional argument: 'db_manager'
Exception: None
---

2025-08-15 19:16:47,507 - __main__ - ERROR - main:main:68
Message: Application crashed: unknown option "-font_size"
Exception: (<class '_tkinter.TclError'>, TclError('unknown option "-font_size"'), <traceback object at 0x0000024745AF9C00>)
---
Traceback (most recent call last):
  File "C:\Users\nolan\personal\personal-projects\Nabu\main.py", line 59, in main
    app = TutorApplication()
  File "C:\Users\nolan\personal\personal-projects\Nabu\core\application.py", line 45, in __init__
    self._initialize_ui()
  File "C:\Users\nolan\personal\personal-projects\Nabu\core\application.py", line 86, in _initialize_ui
    self.conversation_frame = ConversationFrame(
  File "C:\Users\nolan\personal\personal-projects\Nabu\ui\conversation.py", line 37, in __init__
    self._setup_ui()
  File "C:\Users\nolan\personal\personal-projects\Nabu\ui\conversation.py", line 49, in _setup_ui
    self.title_label = self.theme.create_styled_label(
  File "C:\Users\nolan\personal\personal-projects\Nabu\ui\theme.py", line 334, in create_styled_label
    label = tk.Label(
  File "C:\Users\nolan\Anaconda3\lib\tkinter\__init__.py", line 3148, in __init__
    Widget.__init__(self, master, 'label', cnf, kw)
  File "C:\Users\nolan\Anaconda3\lib\tkinter\__init__.py", line 2572, in __init__
    self.tk.call(
_tkinter.TclError: unknown option "-font_size"
2025-08-15 19:17:58,544 - data.database - ERROR - database:get_connection:47
Message: Database operation failed: UNIQUE constraint failed: settings.key
Exception: (<class 'sqlite3.IntegrityError'>, IntegrityError('UNIQUE constraint failed: settings.key'), <traceback object at 0x0000026D5B1ED280>)
---
Traceback (most recent call last):
  File "C:\Users\nolan\personal\personal-projects\Nabu\data\database.py", line 43, in get_connection
    yield conn
  File "C:\Users\nolan\personal\personal-projects\Nabu\data\database.py", line 130, in insert
    cursor = conn.execute(query, tuple(data.values()))
sqlite3.IntegrityError: UNIQUE constraint failed: settings.key
2025-08-15 19:17:58,549 - data.database - ERROR - database:get_connection:47
Message: Database operation failed: UNIQUE constraint failed: settings.key
Exception: (<class 'sqlite3.IntegrityError'>, IntegrityError('UNIQUE constraint failed: settings.key'), <traceback object at 0x0000026D5B1ED280>)
---
Traceback (most recent call last):
  File "C:\Users\nolan\personal\personal-projects\Nabu\data\database.py", line 43, in get_connection
    yield conn
  File "C:\Users\nolan\personal\personal-projects\Nabu\data\database.py", line 130, in insert
    cursor = conn.execute(query, tuple(data.values()))
sqlite3.IntegrityError: UNIQUE constraint failed: settings.key
2025-08-15 19:17:58,556 - data.database - ERROR - database:get_connection:47
Message: Database operation failed: UNIQUE constraint failed: settings.key
Exception: (<class 'sqlite3.IntegrityError'>, IntegrityError('UNIQUE constraint failed: settings.key'), <traceback object at 0x0000026D5B1ED300>)
---
Traceback (most recent call last):
  File "C:\Users\nolan\personal\personal-projects\Nabu\data\database.py", line 43, in get_connection
    yield conn
  File "C:\Users\nolan\personal\personal-projects\Nabu\data\database.py", line 130, in insert
    cursor = conn.execute(query, tuple(data.values()))
sqlite3.IntegrityError: UNIQUE constraint failed: settings.key
2025-08-15 19:17:58,561 - data.database - ERROR - database:get_connection:47
Message: Database operation failed: UNIQUE constraint failed: settings.key
Exception: (<class 'sqlite3.IntegrityError'>, IntegrityError('UNIQUE constraint failed: settings.key'), <traceback object at 0x0000026D5B1ED280>)
---
Traceback (most recent call last):
  File "C:\Users\nolan\personal\personal-projects\Nabu\data\database.py", line 43, in get_connection
    yield conn
  File "C:\Users\nolan\personal\personal-projects\Nabu\data\database.py", line 130, in insert
    cursor = conn.execute(query, tuple(data.values()))
sqlite3.IntegrityError: UNIQUE constraint failed: settings.key
2025-08-15 19:17:58,565 - data.database - ERROR - database:get_connection:47
Message: Database operation failed: UNIQUE constraint failed: settings.key
Exception: (<class 'sqlite3.IntegrityError'>, IntegrityError('UNIQUE constraint failed: settings.key'), <traceback object at 0x0000026D5B1ED300>)
---
Traceback (most recent call last):
  File "C:\Users\nolan\personal\personal-projects\Nabu\data\database.py", line 43, in get_connection
    yield conn
  File "C:\Users\nolan\personal\personal-projects\Nabu\data\database.py", line 130, in insert
    cursor = conn.execute(query, tuple(data.values()))
sqlite3.IntegrityError: UNIQUE constraint failed: settings.key
2025-08-15 19:17:58,576 - data.database - ERROR - database:get_connection:47
Message: Database operation failed: UNIQUE constraint failed: settings.key
Exception: (<class 'sqlite3.IntegrityError'>, IntegrityError('UNIQUE constraint failed: settings.key'), <traceback object at 0x0000026D5B1ED280>)
---
Traceback (most recent call last):
  File "C:\Users\nolan\personal\personal-projects\Nabu\data\database.py", line 43, in get_connection
    yield conn
  File "C:\Users\nolan\personal\personal-projects\Nabu\data\database.py", line 130, in insert
    cursor = conn.execute(query, tuple(data.values()))
sqlite3.IntegrityError: UNIQUE constraint failed: settings.key
2025-08-15 19:17:58,582 - data.database - ERROR - database:get_connection:47
Message: Database operation failed: UNIQUE constraint failed: settings.key
Exception: (<class 'sqlite3.IntegrityError'>, IntegrityError('UNIQUE constraint failed: settings.key'), <traceback object at 0x0000026D5B1ED300>)
---
Traceback (most recent call last):
  File "C:\Users\nolan\personal\personal-projects\Nabu\data\database.py", line 43, in get_connection
    yield conn
  File "C:\Users\nolan\personal\personal-projects\Nabu\data\database.py", line 130, in insert
    cursor = conn.execute(query, tuple(data.values()))
sqlite3.IntegrityError: UNIQUE constraint failed: settings.key
2025-08-15 19:17:58,589 - data.database - ERROR - database:get_connection:47
Message: Database operation failed: UNIQUE constraint failed: settings.key
Exception: (<class 'sqlite3.IntegrityError'>, IntegrityError('UNIQUE constraint failed: settings.key'), <traceback object at 0x0000026D5B1ED280>)
---
Traceback (most recent call last):
  File "C:\Users\nolan\personal\personal-projects\Nabu\data\database.py", line 43, in get_connection
    yield conn
  File "C:\Users\nolan\personal\personal-projects\Nabu\data\database.py", line 130, in insert
    cursor = conn.execute(query, tuple(data.values()))
sqlite3.IntegrityError: UNIQUE constraint failed: settings.key
2025-08-15 19:17:58,595 - data.database - ERROR - database:get_connection:47
Message: Database operation failed: UNIQUE constraint failed: settings.key
Exception: (<class 'sqlite3.IntegrityError'>, IntegrityError('UNIQUE constraint failed: settings.key'), <traceback object at 0x0000026D5B1ED300>)
---
Traceback (most recent call last):
  File "C:\Users\nolan\personal\personal-projects\Nabu\data\database.py", line 43, in get_connection
    yield conn
  File "C:\Users\nolan\personal\personal-projects\Nabu\data\database.py", line 130, in insert
    cursor = conn.execute(query, tuple(data.values()))
sqlite3.IntegrityError: UNIQUE constraint failed: settings.key
2025-08-15 19:17:58,595 - data.database - ERROR - database:get_connection:47
Message: Database operation failed: UNIQUE constraint failed: settings.key
Exception: (<class 'sqlite3.IntegrityError'>, IntegrityError('UNIQUE constraint failed: settings.key'), <traceback object at 0x0000026D5B1ED280>)
---
Traceback (most recent call last):
  File "C:\Users\nolan\personal\personal-projects\Nabu\data\database.py", line 43, in get_connection
    yield conn
  File "C:\Users\nolan\personal\personal-projects\Nabu\data\database.py", line 130, in insert
    cursor = conn.execute(query, tuple(data.values()))
sqlite3.IntegrityError: UNIQUE constraint failed: settings.key
2025-08-15 19:17:58,626 - data.database - ERROR - database:get_connection:47
Message: Database operation failed: UNIQUE constraint failed: vocabulary.word, vocabulary.language
Exception: (<class 'sqlite3.IntegrityError'>, IntegrityError('UNIQUE constraint failed: vocabulary.word, vocabulary.language'), <traceback object at 0x0000026D5B1ED300>)
---
Traceback (most recent call last):
  File "C:\Users\nolan\personal\personal-projects\Nabu\data\database.py", line 43, in get_connection
    yield conn
  File "C:\Users\nolan\personal\personal-projects\Nabu\data\database.py", line 130, in insert
    cursor = conn.execute(query, tuple(data.values()))
sqlite3.IntegrityError: UNIQUE constraint failed: vocabulary.word, vocabulary.language
2025-08-15 19:17:58,633 - data.database - ERROR - database:get_connection:47
Message: Database operation failed: UNIQUE constraint failed: vocabulary.word, vocabulary.language
Exception: (<class 'sqlite3.IntegrityError'>, IntegrityError('UNIQUE constraint failed: vocabulary.word, vocabulary.language'), <traceback object at 0x0000026D5B1ED280>)
---
Traceback (most recent call last):
  File "C:\Users\nolan\personal\personal-projects\Nabu\data\database.py", line 43, in get_connection
    yield conn
  File "C:\Users\nolan\personal\personal-projects\Nabu\data\database.py", line 130, in insert
    cursor = conn.execute(query, tuple(data.values()))
sqlite3.IntegrityError: UNIQUE constraint failed: vocabulary.word, vocabulary.language
2025-08-15 19:18:00,095 - __main__ - ERROR - main:main:68
Message: Application crashed: 'DarkTheme' object has no attribute 'FONTS'
Exception: (<class 'AttributeError'>, AttributeError("'DarkTheme' object has no attribute 'FONTS'"), <traceback object at 0x0000026D5B1E8B40>)
---
Traceback (most recent call last):
  File "C:\Users\nolan\personal\personal-projects\Nabu\main.py", line 59, in main
    app = TutorApplication()
  File "C:\Users\nolan\personal\personal-projects\Nabu\core\application.py", line 45, in __init__
    self._initialize_ui()
  File "C:\Users\nolan\personal\personal-projects\Nabu\core\application.py", line 86, in _initialize_ui
    self.conversation_frame = ConversationFrame(
  File "C:\Users\nolan\personal\personal-projects\Nabu\ui\conversation.py", line 37, in __init__
    self._setup_ui()
  File "C:\Users\nolan\personal\personal-projects\Nabu\ui\conversation.py", line 66, in _setup_ui
    font=(self.theme.FONTS['body'], self.theme.FONT_SIZES['base']),
AttributeError: 'DarkTheme' object has no attribute 'FONTS'
2025-08-15 19:18:41,629 - data.database - ERROR - database:get_connection:47
Message: Database operation failed: UNIQUE constraint failed: settings.key
Exception: (<class 'sqlite3.IntegrityError'>, IntegrityError('UNIQUE constraint failed: settings.key'), <traceback object at 0x000002940EE9B4C0>)
---
Traceback (most recent call last):
  File "C:\Users\nolan\personal\personal-projects\Nabu\data\database.py", line 43, in get_connection
    yield conn
  File "C:\Users\nolan\personal\personal-projects\Nabu\data\database.py", line 130, in insert
    cursor = conn.execute(query, tuple(data.values()))
sqlite3.IntegrityError: UNIQUE constraint failed: settings.key
2025-08-15 19:18:41,635 - data.database - ERROR - database:get_connection:47
Message: Database operation failed: UNIQUE constraint failed: settings.key
Exception: (<class 'sqlite3.IntegrityError'>, IntegrityError('UNIQUE constraint failed: settings.key'), <traceback object at 0x000002940EE9B480>)
---
Traceback (most recent call last):
  File "C:\Users\nolan\personal\personal-projects\Nabu\data\database.py", line 43, in get_connection
    yield conn
  File "C:\Users\nolan\personal\personal-projects\Nabu\data\database.py", line 130, in insert
    cursor = conn.execute(query, tuple(data.values()))
sqlite3.IntegrityError: UNIQUE constraint failed: settings.key
2025-08-15 19:18:41,643 - data.database - ERROR - database:get_connection:47
Message: Database operation failed: UNIQUE constraint failed: settings.key
Exception: (<class 'sqlite3.IntegrityError'>, IntegrityError('UNIQUE constraint failed: settings.key'), <traceback object at 0x000002940EE9B4C0>)
---
Traceback (most recent call last):
  File "C:\Users\nolan\personal\personal-projects\Nabu\data\database.py", line 43, in get_connection
    yield conn
  File "C:\Users\nolan\personal\personal-projects\Nabu\data\database.py", line 130, in insert
    cursor = conn.execute(query, tuple(data.values()))
sqlite3.IntegrityError: UNIQUE constraint failed: settings.key
2025-08-15 19:18:41,649 - data.database - ERROR - database:get_connection:47
Message: Database operation failed: UNIQUE constraint failed: settings.key
Exception: (<class 'sqlite3.IntegrityError'>, IntegrityError('UNIQUE constraint failed: settings.key'), <traceback object at 0x000002940EE9B480>)
---
Traceback (most recent call last):
  File "C:\Users\nolan\personal\personal-projects\Nabu\data\database.py", line 43, in get_connection
    yield conn
  File "C:\Users\nolan\personal\personal-projects\Nabu\data\database.py", line 130, in insert
    cursor = conn.execute(query, tuple(data.values()))
sqlite3.IntegrityError: UNIQUE constraint failed: settings.key
2025-08-15 19:18:41,658 - data.database - ERROR - database:get_connection:47
Message: Database operation failed: UNIQUE constraint failed: settings.key
Exception: (<class 'sqlite3.IntegrityError'>, IntegrityError('UNIQUE constraint failed: settings.key'), <traceback object at 0x000002940EE9B4C0>)
---
Traceback (most recent call last):
  File "C:\Users\nolan\personal\personal-projects\Nabu\data\database.py", line 43, in get_connection
    yield conn
  File "C:\Users\nolan\personal\personal-projects\Nabu\data\database.py", line 130, in insert
    cursor = conn.execute(query, tuple(data.values()))
sqlite3.IntegrityError: UNIQUE constraint failed: settings.key
2025-08-15 19:18:41,663 - data.database - ERROR - database:get_connection:47
Message: Database operation failed: UNIQUE constraint failed: settings.key
Exception: (<class 'sqlite3.IntegrityError'>, IntegrityError('UNIQUE constraint failed: settings.key'), <traceback object at 0x000002940EE9B480>)
---
Traceback (most recent call last):
  File "C:\Users\nolan\personal\personal-projects\Nabu\data\database.py", line 43, in get_connection
    yield conn
  File "C:\Users\nolan\personal\personal-projects\Nabu\data\database.py", line 130, in insert
    cursor = conn.execute(query, tuple(data.values()))
sqlite3.IntegrityError: UNIQUE constraint failed: settings.key
2025-08-15 19:18:41,670 - data.database - ERROR - database:get_connection:47
Message: Database operation failed: UNIQUE constraint failed: settings.key
Exception: (<class 'sqlite3.IntegrityError'>, IntegrityError('UNIQUE constraint failed: settings.key'), <traceback object at 0x000002940EE9B4C0>)
---
Traceback (most recent call last):
  File "C:\Users\nolan\personal\personal-projects\Nabu\data\database.py", line 43, in get_connection
    yield conn
  File "C:\Users\nolan\personal\personal-projects\Nabu\data\database.py", line 130, in insert
    cursor = conn.execute(query, tuple(data.values()))
sqlite3.IntegrityError: UNIQUE constraint failed: settings.key
2025-08-15 19:18:41,679 - data.database - ERROR - database:get_connection:47
Message: Database operation failed: UNIQUE constraint failed: settings.key
Exception: (<class 'sqlite3.IntegrityError'>, IntegrityError('UNIQUE constraint failed: settings.key'), <traceback object at 0x000002940EE9B480>)
---
Traceback (most recent call last):
  File "C:\Users\nolan\personal\personal-projects\Nabu\data\database.py", line 43, in get_connection
    yield conn
  File "C:\Users\nolan\personal\personal-projects\Nabu\data\database.py", line 130, in insert
    cursor = conn.execute(query, tuple(data.values()))
sqlite3.IntegrityError: UNIQUE constraint failed: settings.key
2025-08-15 19:18:41,683 - data.database - ERROR - database:get_connection:47
Message: Database operation failed: UNIQUE constraint failed: settings.key
Exception: (<class 'sqlite3.IntegrityError'>, IntegrityError('UNIQUE constraint failed: settings.key'), <traceback object at 0x000002940EE9B4C0>)
---
Traceback (most recent call last):
  File "C:\Users\nolan\personal\personal-projects\Nabu\data\database.py", line 43, in get_connection
    yield conn
  File "C:\Users\nolan\personal\personal-projects\Nabu\data\database.py", line 130, in insert
    cursor = conn.execute(query, tuple(data.values()))
sqlite3.IntegrityError: UNIQUE constraint failed: settings.key
2025-08-15 19:18:41,693 - data.database - ERROR - database:get_connection:47
Message: Database operation failed: UNIQUE constraint failed: settings.key
Exception: (<class 'sqlite3.IntegrityError'>, IntegrityError('UNIQUE constraint failed: settings.key'), <traceback object at 0x000002940EE9B480>)
---
Traceback (most recent call last):
  File "C:\Users\nolan\personal\personal-projects\Nabu\data\database.py", line 43, in get_connection
    yield conn
  File "C:\Users\nolan\personal\personal-projects\Nabu\data\database.py", line 130, in insert
    cursor = conn.execute(query, tuple(data.values()))
sqlite3.IntegrityError: UNIQUE constraint failed: settings.key
2025-08-15 19:18:41,710 - data.database - ERROR - database:get_connection:47
Message: Database operation failed: UNIQUE constraint failed: vocabulary.word, vocabulary.language
Exception: (<class 'sqlite3.IntegrityError'>, IntegrityError('UNIQUE constraint failed: vocabulary.word, vocabulary.language'), <traceback object at 0x000002940EE9B4C0>)
---
Traceback (most recent call last):
  File "C:\Users\nolan\personal\personal-projects\Nabu\data\database.py", line 43, in get_connection
    yield conn
  File "C:\Users\nolan\personal\personal-projects\Nabu\data\database.py", line 130, in insert
    cursor = conn.execute(query, tuple(data.values()))
sqlite3.IntegrityError: UNIQUE constraint failed: vocabulary.word, vocabulary.language
2025-08-15 19:18:41,721 - data.database - ERROR - database:get_connection:47
Message: Database operation failed: UNIQUE constraint failed: vocabulary.word, vocabulary.language
Exception: (<class 'sqlite3.IntegrityError'>, IntegrityError('UNIQUE constraint failed: vocabulary.word, vocabulary.language'), <traceback object at 0x000002940EE9B480>)
---
Traceback (most recent call last):
  File "C:\Users\nolan\personal\personal-projects\Nabu\data\database.py", line 43, in get_connection
    yield conn
  File "C:\Users\nolan\personal\personal-projects\Nabu\data\database.py", line 130, in insert
    cursor = conn.execute(query, tuple(data.values()))
sqlite3.IntegrityError: UNIQUE constraint failed: vocabulary.word, vocabulary.language
2025-08-15 19:18:43,290 - __main__ - ERROR - main:main:68
Message: Application crashed: type object 'EventTypes' has no attribute 'USER_MESSAGE'
Exception: (<class 'AttributeError'>, AttributeError("type object 'EventTypes' has no attribute 'USER_MESSAGE'"), <traceback object at 0x000002940EE1DDC0>)
---
Traceback (most recent call last):
  File "C:\Users\nolan\personal\personal-projects\Nabu\main.py", line 59, in main
    app = TutorApplication()
  File "C:\Users\nolan\personal\personal-projects\Nabu\core\application.py", line 45, in __init__
    self._initialize_ui()
  File "C:\Users\nolan\personal\personal-projects\Nabu\core\application.py", line 86, in _initialize_ui
    self.conversation_frame = ConversationFrame(
  File "C:\Users\nolan\personal\personal-projects\Nabu\ui\conversation.py", line 38, in __init__
    self._setup_event_handlers()
  File "C:\Users\nolan\personal\personal-projects\Nabu\ui\conversation.py", line 128, in _setup_event_handlers
    self.event_bus.subscribe(EventTypes.USER_MESSAGE, self._on_user_message)
AttributeError: type object 'EventTypes' has no attribute 'USER_MESSAGE'
2025-08-15 19:19:19,732 - data.database - ERROR - database:get_connection:47
Message: Database operation failed: UNIQUE constraint failed: settings.key
Exception: (<class 'sqlite3.IntegrityError'>, IntegrityError('UNIQUE constraint failed: settings.key'), <traceback object at 0x000001F57636BF00>)
---
Traceback (most recent call last):
  File "C:\Users\nolan\personal\personal-projects\Nabu\data\database.py", line 43, in get_connection
    yield conn
  File "C:\Users\nolan\personal\personal-projects\Nabu\data\database.py", line 130, in insert
    cursor = conn.execute(query, tuple(data.values()))
sqlite3.IntegrityError: UNIQUE constraint failed: settings.key
2025-08-15 19:19:19,739 - data.database - ERROR - database:get_connection:47
Message: Database operation failed: UNIQUE constraint failed: settings.key
Exception: (<class 'sqlite3.IntegrityError'>, IntegrityError('UNIQUE constraint failed: settings.key'), <traceback object at 0x000001F57636BF00>)
---
Traceback (most recent call last):
  File "C:\Users\nolan\personal\personal-projects\Nabu\data\database.py", line 43, in get_connection
    yield conn
  File "C:\Users\nolan\personal\personal-projects\Nabu\data\database.py", line 130, in insert
    cursor = conn.execute(query, tuple(data.values()))
sqlite3.IntegrityError: UNIQUE constraint failed: settings.key
2025-08-15 19:19:19,779 - data.database - ERROR - database:get_connection:47
Message: Database operation failed: UNIQUE constraint failed: settings.key
Exception: (<class 'sqlite3.IntegrityError'>, IntegrityError('UNIQUE constraint failed: settings.key'), <traceback object at 0x000001F57636BBC0>)
---
Traceback (most recent call last):
  File "C:\Users\nolan\personal\personal-projects\Nabu\data\database.py", line 43, in get_connection
    yield conn
  File "C:\Users\nolan\personal\personal-projects\Nabu\data\database.py", line 130, in insert
    cursor = conn.execute(query, tuple(data.values()))
sqlite3.IntegrityError: UNIQUE constraint failed: settings.key
2025-08-15 19:19:19,795 - data.database - ERROR - database:get_connection:47
Message: Database operation failed: UNIQUE constraint failed: settings.key
Exception: (<class 'sqlite3.IntegrityError'>, IntegrityError('UNIQUE constraint failed: settings.key'), <traceback object at 0x000001F57636BF00>)
---
Traceback (most recent call last):
  File "C:\Users\nolan\personal\personal-projects\Nabu\data\database.py", line 43, in get_connection
    yield conn
  File "C:\Users\nolan\personal\personal-projects\Nabu\data\database.py", line 130, in insert
    cursor = conn.execute(query, tuple(data.values()))
sqlite3.IntegrityError: UNIQUE constraint failed: settings.key
2025-08-15 19:19:19,827 - data.database - ERROR - database:get_connection:47
Message: Database operation failed: UNIQUE constraint failed: settings.key
Exception: (<class 'sqlite3.IntegrityError'>, IntegrityError('UNIQUE constraint failed: settings.key'), <traceback object at 0x000001F57636BBC0>)
---
Traceback (most recent call last):
  File "C:\Users\nolan\personal\personal-projects\Nabu\data\database.py", line 43, in get_connection
    yield conn
  File "C:\Users\nolan\personal\personal-projects\Nabu\data\database.py", line 130, in insert
    cursor = conn.execute(query, tuple(data.values()))
sqlite3.IntegrityError: UNIQUE constraint failed: settings.key
2025-08-15 19:19:19,840 - data.database - ERROR - database:get_connection:47
Message: Database operation failed: UNIQUE constraint failed: settings.key
Exception: (<class 'sqlite3.IntegrityError'>, IntegrityError('UNIQUE constraint failed: settings.key'), <traceback object at 0x000001F57636BF00>)
---
Traceback (most recent call last):
  File "C:\Users\nolan\personal\personal-projects\Nabu\data\database.py", line 43, in get_connection
    yield conn
  File "C:\Users\nolan\personal\personal-projects\Nabu\data\database.py", line 130, in insert
    cursor = conn.execute(query, tuple(data.values()))
sqlite3.IntegrityError: UNIQUE constraint failed: settings.key
2025-08-15 19:19:19,848 - data.database - ERROR - database:get_connection:47
Message: Database operation failed: UNIQUE constraint failed: settings.key
Exception: (<class 'sqlite3.IntegrityError'>, IntegrityError('UNIQUE constraint failed: settings.key'), <traceback object at 0x000001F57636BBC0>)
---
Traceback (most recent call last):
  File "C:\Users\nolan\personal\personal-projects\Nabu\data\database.py", line 43, in get_connection
    yield conn
  File "C:\Users\nolan\personal\personal-projects\Nabu\data\database.py", line 130, in insert
    cursor = conn.execute(query, tuple(data.values()))
sqlite3.IntegrityError: UNIQUE constraint failed: settings.key
2025-08-15 19:19:19,862 - data.database - ERROR - database:get_connection:47
Message: Database operation failed: UNIQUE constraint failed: settings.key
Exception: (<class 'sqlite3.IntegrityError'>, IntegrityError('UNIQUE constraint failed: settings.key'), <traceback object at 0x000001F57636BF00>)
---
Traceback (most recent call last):
  File "C:\Users\nolan\personal\personal-projects\Nabu\data\database.py", line 43, in get_connection
    yield conn
  File "C:\Users\nolan\personal\personal-projects\Nabu\data\database.py", line 130, in insert
    cursor = conn.execute(query, tuple(data.values()))
sqlite3.IntegrityError: UNIQUE constraint failed: settings.key
2025-08-15 19:19:19,870 - data.database - ERROR - database:get_connection:47
Message: Database operation failed: UNIQUE constraint failed: settings.key
Exception: (<class 'sqlite3.IntegrityError'>, IntegrityError('UNIQUE constraint failed: settings.key'), <traceback object at 0x000001F57636BBC0>)
---
Traceback (most recent call last):
  File "C:\Users\nolan\personal\personal-projects\Nabu\data\database.py", line 43, in get_connection
    yield conn
  File "C:\Users\nolan\personal\personal-projects\Nabu\data\database.py", line 130, in insert
    cursor = conn.execute(query, tuple(data.values()))
sqlite3.IntegrityError: UNIQUE constraint failed: settings.key
2025-08-15 19:19:19,881 - data.database - ERROR - database:get_connection:47
Message: Database operation failed: UNIQUE constraint failed: settings.key
Exception: (<class 'sqlite3.IntegrityError'>, IntegrityError('UNIQUE constraint failed: settings.key'), <traceback object at 0x000001F57636BF00>)
---
Traceback (most recent call last):
  File "C:\Users\nolan\personal\personal-projects\Nabu\data\database.py", line 43, in get_connection
    yield conn
  File "C:\Users\nolan\personal\personal-projects\Nabu\data\database.py", line 130, in insert
    cursor = conn.execute(query, tuple(data.values()))
sqlite3.IntegrityError: UNIQUE constraint failed: settings.key
2025-08-15 19:19:19,915 - data.database - ERROR - database:get_connection:47
Message: Database operation failed: UNIQUE constraint failed: vocabulary.word, vocabulary.language
Exception: (<class 'sqlite3.IntegrityError'>, IntegrityError('UNIQUE constraint failed: vocabulary.word, vocabulary.language'), <traceback object at 0x000001F57636BBC0>)
---
Traceback (most recent call last):
  File "C:\Users\nolan\personal\personal-projects\Nabu\data\database.py", line 43, in get_connection
    yield conn
  File "C:\Users\nolan\personal\personal-projects\Nabu\data\database.py", line 130, in insert
    cursor = conn.execute(query, tuple(data.values()))
sqlite3.IntegrityError: UNIQUE constraint failed: vocabulary.word, vocabulary.language
2025-08-15 19:19:19,923 - data.database - ERROR - database:get_connection:47
Message: Database operation failed: UNIQUE constraint failed: vocabulary.word, vocabulary.language
Exception: (<class 'sqlite3.IntegrityError'>, IntegrityError('UNIQUE constraint failed: vocabulary.word, vocabulary.language'), <traceback object at 0x000001F57636BF00>)
---
Traceback (most recent call last):
  File "C:\Users\nolan\personal\personal-projects\Nabu\data\database.py", line 43, in get_connection
    yield conn
  File "C:\Users\nolan\personal\personal-projects\Nabu\data\database.py", line 130, in insert
    cursor = conn.execute(query, tuple(data.values()))
sqlite3.IntegrityError: UNIQUE constraint failed: vocabulary.word, vocabulary.language
2025-08-15 19:19:41,984 - audio.voice_loop - ERROR - voice_loop:_process_audio:271
Message: Audio processing error: 

You tried to access openai.Audio, but this is no longer supported in openai>=1.0.0 - see the README at https://github.com/openai/openai-python for the API.

You can run `openai migrate` to automatically upgrade your codebase to use the 1.0.0 interface. 

Alternatively, you can pin your installation to the old version, e.g. `pip install openai==0.28`

A detailed migration guide is available here: https://github.com/openai/openai-python/discussions/742

Exception: None
---

2025-08-15 19:19:51,703 - audio.voice_loop - ERROR - voice_loop:_process_audio:271
Message: Audio processing error: 

You tried to access openai.Audio, but this is no longer supported in openai>=1.0.0 - see the README at https://github.com/openai/openai-python for the API.

You can run `openai migrate` to automatically upgrade your codebase to use the 1.0.0 interface. 

Alternatively, you can pin your installation to the old version, e.g. `pip install openai==0.28`

A detailed migration guide is available here: https://github.com/openai/openai-python/discussions/742

Exception: None
---

2025-08-15 19:19:55,874 - audio.voice_loop - ERROR - voice_loop:_process_audio:271
Message: Audio processing error: 

You tried to access openai.Audio, but this is no longer supported in openai>=1.0.0 - see the README at https://github.com/openai/openai-python for the API.

You can run `openai migrate` to automatically upgrade your codebase to use the 1.0.0 interface. 

Alternatively, you can pin your installation to the old version, e.g. `pip install openai==0.28`

A detailed migration guide is available here: https://github.com/openai/openai-python/discussions/742

Exception: None
---

2025-08-15 19:19:56,886 - core.event_bus - ERROR - event_bus:publish:69
Message: Error in event callback for audio_error: main thread is not in main loop
Exception: (<class 'RuntimeError'>, RuntimeError('main thread is not in main loop'), <traceback object at 0x000001F57635AE40>)
---
Traceback (most recent call last):
  File "C:\Users\nolan\personal\personal-projects\Nabu\audio\voice_loop.py", line 268, in _process_audio
    raise e
  File "C:\Users\nolan\personal\personal-projects\Nabu\audio\voice_loop.py", line 234, in _process_audio
    transcript = openai.Audio.transcribe(
  File "C:\Users\nolan\personal\personal-projects\Nabu\Nabu-venv\lib\site-packages\openai\lib\_old_api.py", line 39, in __call__
    raise APIRemovedInV1(symbol=self._symbol)
openai.lib._old_api.APIRemovedInV1: 

You tried to access openai.Audio, but this is no longer supported in openai>=1.0.0 - see the README at https://github.com/openai/openai-python for the API.

You can run `openai migrate` to automatically upgrade your codebase to use the 1.0.0 interface. 

Alternatively, you can pin your installation to the old version, e.g. `pip install openai==0.28`

A detailed migration guide is available here: https://github.com/openai/openai-python/discussions/742


During handling of the above exception, another exception occurred:

Traceback (most recent call last):
  File "C:\Users\nolan\personal\personal-projects\Nabu\core\event_bus.py", line 67, in publish
    callback(data)
  File "C:\Users\nolan\personal\personal-projects\Nabu\ui\conversation.py", line 253, in _on_audio_error
    self.status_label.config(text=f"Audio Error: {error}")
  File "C:\Users\nolan\Anaconda3\lib\tkinter\__init__.py", line 1646, in configure
    return self._configure('configure', cnf, kw)
  File "C:\Users\nolan\Anaconda3\lib\tkinter\__init__.py", line 1636, in _configure
    self.tk.call(_flatten((self._w, cmd)) + self._options(cnf))
RuntimeError: main thread is not in main loop
2025-08-15 19:20:28,308 - data.database - ERROR - database:get_connection:47
Message: Database operation failed: UNIQUE constraint failed: settings.key
Exception: (<class 'sqlite3.IntegrityError'>, IntegrityError('UNIQUE constraint failed: settings.key'), <traceback object at 0x000001D76379AE00>)
---
Traceback (most recent call last):
  File "C:\Users\nolan\personal\personal-projects\Nabu\data\database.py", line 43, in get_connection
    yield conn
  File "C:\Users\nolan\personal\personal-projects\Nabu\data\database.py", line 130, in insert
    cursor = conn.execute(query, tuple(data.values()))
sqlite3.IntegrityError: UNIQUE constraint failed: settings.key
2025-08-15 19:20:28,313 - data.database - ERROR - database:get_connection:47
Message: Database operation failed: UNIQUE constraint failed: settings.key
Exception: (<class 'sqlite3.IntegrityError'>, IntegrityError('UNIQUE constraint failed: settings.key'), <traceback object at 0x000001D76379AF80>)
---
Traceback (most recent call last):
  File "C:\Users\nolan\personal\personal-projects\Nabu\data\database.py", line 43, in get_connection
    yield conn
  File "C:\Users\nolan\personal\personal-projects\Nabu\data\database.py", line 130, in insert
    cursor = conn.execute(query, tuple(data.values()))
sqlite3.IntegrityError: UNIQUE constraint failed: settings.key
2025-08-15 19:20:28,319 - data.database - ERROR - database:get_connection:47
Message: Database operation failed: UNIQUE constraint failed: settings.key
Exception: (<class 'sqlite3.IntegrityError'>, IntegrityError('UNIQUE constraint failed: settings.key'), <traceback object at 0x000001D76379AE00>)
---
Traceback (most recent call last):
  File "C:\Users\nolan\personal\personal-projects\Nabu\data\database.py", line 43, in get_connection
    yield conn
  File "C:\Users\nolan\personal\personal-projects\Nabu\data\database.py", line 130, in insert
    cursor = conn.execute(query, tuple(data.values()))
sqlite3.IntegrityError: UNIQUE constraint failed: settings.key
2025-08-15 19:20:28,323 - data.database - ERROR - database:get_connection:47
Message: Database operation failed: UNIQUE constraint failed: settings.key
Exception: (<class 'sqlite3.IntegrityError'>, IntegrityError('UNIQUE constraint failed: settings.key'), <traceback object at 0x000001D76379AF80>)
---
Traceback (most recent call last):
  File "C:\Users\nolan\personal\personal-projects\Nabu\data\database.py", line 43, in get_connection
    yield conn
  File "C:\Users\nolan\personal\personal-projects\Nabu\data\database.py", line 130, in insert
    cursor = conn.execute(query, tuple(data.values()))
sqlite3.IntegrityError: UNIQUE constraint failed: settings.key
2025-08-15 19:20:28,332 - data.database - ERROR - database:get_connection:47
Message: Database operation failed: UNIQUE constraint failed: settings.key
Exception: (<class 'sqlite3.IntegrityError'>, IntegrityError('UNIQUE constraint failed: settings.key'), <traceback object at 0x000001D76379AE00>)
---
Traceback (most recent call last):
  File "C:\Users\nolan\personal\personal-projects\Nabu\data\database.py", line 43, in get_connection
    yield conn
  File "C:\Users\nolan\personal\personal-projects\Nabu\data\database.py", line 130, in insert
    cursor = conn.execute(query, tuple(data.values()))
sqlite3.IntegrityError: UNIQUE constraint failed: settings.key
2025-08-15 19:20:28,338 - data.database - ERROR - database:get_connection:47
Message: Database operation failed: UNIQUE constraint failed: settings.key
Exception: (<class 'sqlite3.IntegrityError'>, IntegrityError('UNIQUE constraint failed: settings.key'), <traceback object at 0x000001D76379AF80>)
---
Traceback (most recent call last):
  File "C:\Users\nolan\personal\personal-projects\Nabu\data\database.py", line 43, in get_connection
    yield conn
  File "C:\Users\nolan\personal\personal-projects\Nabu\data\database.py", line 130, in insert
    cursor = conn.execute(query, tuple(data.values()))
sqlite3.IntegrityError: UNIQUE constraint failed: settings.key
2025-08-15 19:20:28,343 - data.database - ERROR - database:get_connection:47
Message: Database operation failed: UNIQUE constraint failed: settings.key
Exception: (<class 'sqlite3.IntegrityError'>, IntegrityError('UNIQUE constraint failed: settings.key'), <traceback object at 0x000001D76379AE00>)
---
Traceback (most recent call last):
  File "C:\Users\nolan\personal\personal-projects\Nabu\data\database.py", line 43, in get_connection
    yield conn
  File "C:\Users\nolan\personal\personal-projects\Nabu\data\database.py", line 130, in insert
    cursor = conn.execute(query, tuple(data.values()))
sqlite3.IntegrityError: UNIQUE constraint failed: settings.key
2025-08-15 19:20:28,351 - data.database - ERROR - database:get_connection:47
Message: Database operation failed: UNIQUE constraint failed: settings.key
Exception: (<class 'sqlite3.IntegrityError'>, IntegrityError('UNIQUE constraint failed: settings.key'), <traceback object at 0x000001D76379AF80>)
---
Traceback (most recent call last):
  File "C:\Users\nolan\personal\personal-projects\Nabu\data\database.py", line 43, in get_connection
    yield conn
  File "C:\Users\nolan\personal\personal-projects\Nabu\data\database.py", line 130, in insert
    cursor = conn.execute(query, tuple(data.values()))
sqlite3.IntegrityError: UNIQUE constraint failed: settings.key
2025-08-15 19:20:28,357 - data.database - ERROR - database:get_connection:47
Message: Database operation failed: UNIQUE constraint failed: settings.key
Exception: (<class 'sqlite3.IntegrityError'>, IntegrityError('UNIQUE constraint failed: settings.key'), <traceback object at 0x000001D76379AE00>)
---
Traceback (most recent call last):
  File "C:\Users\nolan\personal\personal-projects\Nabu\data\database.py", line 43, in get_connection
    yield conn
  File "C:\Users\nolan\personal\personal-projects\Nabu\data\database.py", line 130, in insert
    cursor = conn.execute(query, tuple(data.values()))
sqlite3.IntegrityError: UNIQUE constraint failed: settings.key
2025-08-15 19:20:28,364 - data.database - ERROR - database:get_connection:47
Message: Database operation failed: UNIQUE constraint failed: settings.key
Exception: (<class 'sqlite3.IntegrityError'>, IntegrityError('UNIQUE constraint failed: settings.key'), <traceback object at 0x000001D76379AF80>)
---
Traceback (most recent call last):
  File "C:\Users\nolan\personal\personal-projects\Nabu\data\database.py", line 43, in get_connection
    yield conn
  File "C:\Users\nolan\personal\personal-projects\Nabu\data\database.py", line 130, in insert
    cursor = conn.execute(query, tuple(data.values()))
sqlite3.IntegrityError: UNIQUE constraint failed: settings.key
2025-08-15 19:20:28,383 - data.database - ERROR - database:get_connection:47
Message: Database operation failed: UNIQUE constraint failed: vocabulary.word, vocabulary.language
Exception: (<class 'sqlite3.IntegrityError'>, IntegrityError('UNIQUE constraint failed: vocabulary.word, vocabulary.language'), <traceback object at 0x000001D76379AE00>)
---
Traceback (most recent call last):
  File "C:\Users\nolan\personal\personal-projects\Nabu\data\database.py", line 43, in get_connection
    yield conn
  File "C:\Users\nolan\personal\personal-projects\Nabu\data\database.py", line 130, in insert
    cursor = conn.execute(query, tuple(data.values()))
sqlite3.IntegrityError: UNIQUE constraint failed: vocabulary.word, vocabulary.language
2025-08-15 19:20:28,389 - data.database - ERROR - database:get_connection:47
Message: Database operation failed: UNIQUE constraint failed: vocabulary.word, vocabulary.language
Exception: (<class 'sqlite3.IntegrityError'>, IntegrityError('UNIQUE constraint failed: vocabulary.word, vocabulary.language'), <traceback object at 0x000001D76379AF80>)
---
Traceback (most recent call last):
  File "C:\Users\nolan\personal\personal-projects\Nabu\data\database.py", line 43, in get_connection
    yield conn
  File "C:\Users\nolan\personal\personal-projects\Nabu\data\database.py", line 130, in insert
    cursor = conn.execute(query, tuple(data.values()))
sqlite3.IntegrityError: UNIQUE constraint failed: vocabulary.word, vocabulary.language
2025-08-15 19:20:45,858 - audio.voice_loop - ERROR - voice_loop:_process_audio:271
Message: Audio processing error: 

You tried to access openai.Audio, but this is no longer supported in openai>=1.0.0 - see the README at https://github.com/openai/openai-python for the API.

You can run `openai migrate` to automatically upgrade your codebase to use the 1.0.0 interface. 

Alternatively, you can pin your installation to the old version, e.g. `pip install openai==0.28`

A detailed migration guide is available here: https://github.com/openai/openai-python/discussions/742

Exception: None
---

2025-08-15 19:20:58,843 - data.database - ERROR - database:get_connection:47
Message: Database operation failed: Error binding parameter 2 - probably unsupported type.
Exception: (<class 'sqlite3.InterfaceError'>, InterfaceError('Error binding parameter 2 - probably unsupported type.'), <traceback object at 0x000001D763728E80>)
---
Traceback (most recent call last):
  File "C:\Users\nolan\personal\personal-projects\Nabu\data\database.py", line 43, in get_connection
    yield conn
  File "C:\Users\nolan\personal\personal-projects\Nabu\data\database.py", line 140, in update
    cursor = conn.execute(query, tuple(data.values()) + where_params)
sqlite3.InterfaceError: Error binding parameter 2 - probably unsupported type.
2025-08-15 19:20:58,846 - core.session_manager - ERROR - session_manager:_update_session_in_db:330
Message: Failed to update session in database: Error binding parameter 2 - probably unsupported type.
Exception: (<class 'sqlite3.InterfaceError'>, InterfaceError('Error binding parameter 2 - probably unsupported type.'), <traceback object at 0x000001D763635040>)
---
Traceback (most recent call last):
  File "C:\Users\nolan\personal\personal-projects\Nabu\core\session_manager.py", line 327, in _update_session_in_db
    self.db.update('learning_sessions', data, 'id = ?', (session.session_id,))
  File "C:\Users\nolan\personal\personal-projects\Nabu\data\database.py", line 140, in update
    cursor = conn.execute(query, tuple(data.values()) + where_params)
sqlite3.InterfaceError: Error binding parameter 2 - probably unsupported type.
2025-08-15 19:20:58,882 - audio.voice_loop - ERROR - voice_loop:_process_audio:271
Message: Audio processing error: 

You tried to access openai.Audio, but this is no longer supported in openai>=1.0.0 - see the README at https://github.com/openai/openai-python for the API.

You can run `openai migrate` to automatically upgrade your codebase to use the 1.0.0 interface. 

Alternatively, you can pin your installation to the old version, e.g. `pip install openai==0.28`

A detailed migration guide is available here: https://github.com/openai/openai-python/discussions/742

Exception: None
---

2025-08-15 19:20:58,918 - ui.conversation - ERROR - conversation:_end_session:195
Message: Failed to end session: maximum recursion depth exceeded while calling a Python object
Exception: None
---

2025-08-15 19:21:15,683 - audio.voice_loop - ERROR - voice_loop:_process_audio:271
Message: Audio processing error: 

You tried to access openai.Audio, but this is no longer supported in openai>=1.0.0 - see the README at https://github.com/openai/openai-python for the API.

You can run `openai migrate` to automatically upgrade your codebase to use the 1.0.0 interface. 

Alternatively, you can pin your installation to the old version, e.g. `pip install openai==0.28`

A detailed migration guide is available here: https://github.com/openai/openai-python/discussions/742

Exception: None
---

2025-08-15 19:23:45,507 - data.database - ERROR - database:get_connection:47
Message: Database operation failed: UNIQUE constraint failed: settings.key
Exception: (<class 'sqlite3.IntegrityError'>, IntegrityError('UNIQUE constraint failed: settings.key'), <traceback object at 0x000001D21971F200>)
---
Traceback (most recent call last):
  File "C:\Users\nolan\personal\personal-projects\Nabu\data\database.py", line 43, in get_connection
    yield conn
  File "C:\Users\nolan\personal\personal-projects\Nabu\data\database.py", line 130, in insert
    cursor = conn.execute(query, tuple(data.values()))
sqlite3.IntegrityError: UNIQUE constraint failed: settings.key
2025-08-15 19:23:45,512 - data.database - ERROR - database:get_connection:47
Message: Database operation failed: UNIQUE constraint failed: settings.key
Exception: (<class 'sqlite3.IntegrityError'>, IntegrityError('UNIQUE constraint failed: settings.key'), <traceback object at 0x000001D21971F980>)
---
Traceback (most recent call last):
  File "C:\Users\nolan\personal\personal-projects\Nabu\data\database.py", line 43, in get_connection
    yield conn
  File "C:\Users\nolan\personal\personal-projects\Nabu\data\database.py", line 130, in insert
    cursor = conn.execute(query, tuple(data.values()))
sqlite3.IntegrityError: UNIQUE constraint failed: settings.key
2025-08-15 19:23:45,522 - data.database - ERROR - database:get_connection:47
Message: Database operation failed: UNIQUE constraint failed: settings.key
Exception: (<class 'sqlite3.IntegrityError'>, IntegrityError('UNIQUE constraint failed: settings.key'), <traceback object at 0x000001D21971F200>)
---
Traceback (most recent call last):
  File "C:\Users\nolan\personal\personal-projects\Nabu\data\database.py", line 43, in get_connection
    yield conn
  File "C:\Users\nolan\personal\personal-projects\Nabu\data\database.py", line 130, in insert
    cursor = conn.execute(query, tuple(data.values()))
sqlite3.IntegrityError: UNIQUE constraint failed: settings.key
2025-08-15 19:23:45,528 - data.database - ERROR - database:get_connection:47
Message: Database operation failed: UNIQUE constraint failed: settings.key
Exception: (<class 'sqlite3.IntegrityError'>, IntegrityError('UNIQUE constraint failed: settings.key'), <traceback object at 0x000001D21971F980>)
---
Traceback (most recent call last):
  File "C:\Users\nolan\personal\personal-projects\Nabu\data\database.py", line 43, in get_connection
    yield conn
  File "C:\Users\nolan\personal\personal-projects\Nabu\data\database.py", line 130, in insert
    cursor = conn.execute(query, tuple(data.values()))
sqlite3.IntegrityError: UNIQUE constraint failed: settings.key
2025-08-15 19:23:45,533 - data.database - ERROR - database:get_connection:47
Message: Database operation failed: UNIQUE constraint failed: settings.key
Exception: (<class 'sqlite3.IntegrityError'>, IntegrityError('UNIQUE constraint failed: settings.key'), <traceback object at 0x000001D21971F200>)
---
Traceback (most recent call last):
  File "C:\Users\nolan\personal\personal-projects\Nabu\data\database.py", line 43, in get_connection
    yield conn
  File "C:\Users\nolan\personal\personal-projects\Nabu\data\database.py", line 130, in insert
    cursor = conn.execute(query, tuple(data.values()))
sqlite3.IntegrityError: UNIQUE constraint failed: settings.key
2025-08-15 19:23:45,542 - data.database - ERROR - database:get_connection:47
Message: Database operation failed: UNIQUE constraint failed: settings.key
Exception: (<class 'sqlite3.IntegrityError'>, IntegrityError('UNIQUE constraint failed: settings.key'), <traceback object at 0x000001D21971F980>)
---
Traceback (most recent call last):
  File "C:\Users\nolan\personal\personal-projects\Nabu\data\database.py", line 43, in get_connection
    yield conn
  File "C:\Users\nolan\personal\personal-projects\Nabu\data\database.py", line 130, in insert
    cursor = conn.execute(query, tuple(data.values()))
sqlite3.IntegrityError: UNIQUE constraint failed: settings.key
2025-08-15 19:23:45,542 - data.database - ERROR - database:get_connection:47
Message: Database operation failed: UNIQUE constraint failed: settings.key
Exception: (<class 'sqlite3.IntegrityError'>, IntegrityError('UNIQUE constraint failed: settings.key'), <traceback object at 0x000001D21971F200>)
---
Traceback (most recent call last):
  File "C:\Users\nolan\personal\personal-projects\Nabu\data\database.py", line 43, in get_connection
    yield conn
  File "C:\Users\nolan\personal\personal-projects\Nabu\data\database.py", line 130, in insert
    cursor = conn.execute(query, tuple(data.values()))
sqlite3.IntegrityError: UNIQUE constraint failed: settings.key
2025-08-15 19:23:45,542 - data.database - ERROR - database:get_connection:47
Message: Database operation failed: UNIQUE constraint failed: settings.key
Exception: (<class 'sqlite3.IntegrityError'>, IntegrityError('UNIQUE constraint failed: settings.key'), <traceback object at 0x000001D21971F980>)
---
Traceback (most recent call last):
  File "C:\Users\nolan\personal\personal-projects\Nabu\data\database.py", line 43, in get_connection
    yield conn
  File "C:\Users\nolan\personal\personal-projects\Nabu\data\database.py", line 130, in insert
    cursor = conn.execute(query, tuple(data.values()))
sqlite3.IntegrityError: UNIQUE constraint failed: settings.key
2025-08-15 19:23:45,559 - data.database - ERROR - database:get_connection:47
Message: Database operation failed: UNIQUE constraint failed: settings.key
Exception: (<class 'sqlite3.IntegrityError'>, IntegrityError('UNIQUE constraint failed: settings.key'), <traceback object at 0x000001D21971F200>)
---
Traceback (most recent call last):
  File "C:\Users\nolan\personal\personal-projects\Nabu\data\database.py", line 43, in get_connection
    yield conn
  File "C:\Users\nolan\personal\personal-projects\Nabu\data\database.py", line 130, in insert
    cursor = conn.execute(query, tuple(data.values()))
sqlite3.IntegrityError: UNIQUE constraint failed: settings.key
2025-08-15 19:23:45,565 - data.database - ERROR - database:get_connection:47
Message: Database operation failed: UNIQUE constraint failed: settings.key
Exception: (<class 'sqlite3.IntegrityError'>, IntegrityError('UNIQUE constraint failed: settings.key'), <traceback object at 0x000001D21971F980>)
---
Traceback (most recent call last):
  File "C:\Users\nolan\personal\personal-projects\Nabu\data\database.py", line 43, in get_connection
    yield conn
  File "C:\Users\nolan\personal\personal-projects\Nabu\data\database.py", line 130, in insert
    cursor = conn.execute(query, tuple(data.values()))
sqlite3.IntegrityError: UNIQUE constraint failed: settings.key
2025-08-15 19:23:45,595 - data.database - ERROR - database:get_connection:47
Message: Database operation failed: UNIQUE constraint failed: vocabulary.word, vocabulary.language
Exception: (<class 'sqlite3.IntegrityError'>, IntegrityError('UNIQUE constraint failed: vocabulary.word, vocabulary.language'), <traceback object at 0x000001D21971F200>)
---
Traceback (most recent call last):
  File "C:\Users\nolan\personal\personal-projects\Nabu\data\database.py", line 43, in get_connection
    yield conn
  File "C:\Users\nolan\personal\personal-projects\Nabu\data\database.py", line 130, in insert
    cursor = conn.execute(query, tuple(data.values()))
sqlite3.IntegrityError: UNIQUE constraint failed: vocabulary.word, vocabulary.language
2025-08-15 19:23:45,602 - data.database - ERROR - database:get_connection:47
Message: Database operation failed: UNIQUE constraint failed: vocabulary.word, vocabulary.language
Exception: (<class 'sqlite3.IntegrityError'>, IntegrityError('UNIQUE constraint failed: vocabulary.word, vocabulary.language'), <traceback object at 0x000001D21971F980>)
---
Traceback (most recent call last):
  File "C:\Users\nolan\personal\personal-projects\Nabu\data\database.py", line 43, in get_connection
    yield conn
  File "C:\Users\nolan\personal\personal-projects\Nabu\data\database.py", line 130, in insert
    cursor = conn.execute(query, tuple(data.values()))
sqlite3.IntegrityError: UNIQUE constraint failed: vocabulary.word, vocabulary.language
2025-08-15 19:30:28,964 - data.database - ERROR - database:get_connection:47
Message: Database operation failed: UNIQUE constraint failed: settings.key
Exception: (<class 'sqlite3.IntegrityError'>, IntegrityError('UNIQUE constraint failed: settings.key'), <traceback object at 0x0000019FA25DD480>)
---
Traceback (most recent call last):
  File "C:\Users\nolan\personal\personal-projects\Nabu\data\database.py", line 43, in get_connection
    yield conn
  File "C:\Users\nolan\personal\personal-projects\Nabu\data\database.py", line 130, in insert
    cursor = conn.execute(query, tuple(data.values()))
sqlite3.IntegrityError: UNIQUE constraint failed: settings.key
2025-08-15 19:30:28,973 - data.database - ERROR - database:get_connection:47
Message: Database operation failed: UNIQUE constraint failed: settings.key
Exception: (<class 'sqlite3.IntegrityError'>, IntegrityError('UNIQUE constraint failed: settings.key'), <traceback object at 0x0000019FA25DD840>)
---
Traceback (most recent call last):
  File "C:\Users\nolan\personal\personal-projects\Nabu\data\database.py", line 43, in get_connection
    yield conn
  File "C:\Users\nolan\personal\personal-projects\Nabu\data\database.py", line 130, in insert
    cursor = conn.execute(query, tuple(data.values()))
sqlite3.IntegrityError: UNIQUE constraint failed: settings.key
2025-08-15 19:30:28,980 - data.database - ERROR - database:get_connection:47
Message: Database operation failed: UNIQUE constraint failed: settings.key
Exception: (<class 'sqlite3.IntegrityError'>, IntegrityError('UNIQUE constraint failed: settings.key'), <traceback object at 0x0000019FA25DD480>)
---
Traceback (most recent call last):
  File "C:\Users\nolan\personal\personal-projects\Nabu\data\database.py", line 43, in get_connection
    yield conn
  File "C:\Users\nolan\personal\personal-projects\Nabu\data\database.py", line 130, in insert
    cursor = conn.execute(query, tuple(data.values()))
sqlite3.IntegrityError: UNIQUE constraint failed: settings.key
2025-08-15 19:30:28,989 - data.database - ERROR - database:get_connection:47
Message: Database operation failed: UNIQUE constraint failed: settings.key
Exception: (<class 'sqlite3.IntegrityError'>, IntegrityError('UNIQUE constraint failed: settings.key'), <traceback object at 0x0000019FA25DD840>)
---
Traceback (most recent call last):
  File "C:\Users\nolan\personal\personal-projects\Nabu\data\database.py", line 43, in get_connection
    yield conn
  File "C:\Users\nolan\personal\personal-projects\Nabu\data\database.py", line 130, in insert
    cursor = conn.execute(query, tuple(data.values()))
sqlite3.IntegrityError: UNIQUE constraint failed: settings.key
2025-08-15 19:30:28,995 - data.database - ERROR - database:get_connection:47
Message: Database operation failed: UNIQUE constraint failed: settings.key
Exception: (<class 'sqlite3.IntegrityError'>, IntegrityError('UNIQUE constraint failed: settings.key'), <traceback object at 0x0000019FA25DD480>)
---
Traceback (most recent call last):
  File "C:\Users\nolan\personal\personal-projects\Nabu\data\database.py", line 43, in get_connection
    yield conn
  File "C:\Users\nolan\personal\personal-projects\Nabu\data\database.py", line 130, in insert
    cursor = conn.execute(query, tuple(data.values()))
sqlite3.IntegrityError: UNIQUE constraint failed: settings.key
2025-08-15 19:30:29,004 - data.database - ERROR - database:get_connection:47
Message: Database operation failed: UNIQUE constraint failed: settings.key
Exception: (<class 'sqlite3.IntegrityError'>, IntegrityError('UNIQUE constraint failed: settings.key'), <traceback object at 0x0000019FA25DD840>)
---
Traceback (most recent call last):
  File "C:\Users\nolan\personal\personal-projects\Nabu\data\database.py", line 43, in get_connection
    yield conn
  File "C:\Users\nolan\personal\personal-projects\Nabu\data\database.py", line 130, in insert
    cursor = conn.execute(query, tuple(data.values()))
sqlite3.IntegrityError: UNIQUE constraint failed: settings.key
2025-08-15 19:30:29,012 - data.database - ERROR - database:get_connection:47
Message: Database operation failed: UNIQUE constraint failed: settings.key
Exception: (<class 'sqlite3.IntegrityError'>, IntegrityError('UNIQUE constraint failed: settings.key'), <traceback object at 0x0000019FA25DD480>)
---
Traceback (most recent call last):
  File "C:\Users\nolan\personal\personal-projects\Nabu\data\database.py", line 43, in get_connection
    yield conn
  File "C:\Users\nolan\personal\personal-projects\Nabu\data\database.py", line 130, in insert
    cursor = conn.execute(query, tuple(data.values()))
sqlite3.IntegrityError: UNIQUE constraint failed: settings.key
2025-08-15 19:30:29,022 - data.database - ERROR - database:get_connection:47
Message: Database operation failed: UNIQUE constraint failed: settings.key
Exception: (<class 'sqlite3.IntegrityError'>, IntegrityError('UNIQUE constraint failed: settings.key'), <traceback object at 0x0000019FA25DD840>)
---
Traceback (most recent call last):
  File "C:\Users\nolan\personal\personal-projects\Nabu\data\database.py", line 43, in get_connection
    yield conn
  File "C:\Users\nolan\personal\personal-projects\Nabu\data\database.py", line 130, in insert
    cursor = conn.execute(query, tuple(data.values()))
sqlite3.IntegrityError: UNIQUE constraint failed: settings.key
2025-08-15 19:30:29,027 - data.database - ERROR - database:get_connection:47
Message: Database operation failed: UNIQUE constraint failed: settings.key
Exception: (<class 'sqlite3.IntegrityError'>, IntegrityError('UNIQUE constraint failed: settings.key'), <traceback object at 0x0000019FA25DD480>)
---
Traceback (most recent call last):
  File "C:\Users\nolan\personal\personal-projects\Nabu\data\database.py", line 43, in get_connection
    yield conn
  File "C:\Users\nolan\personal\personal-projects\Nabu\data\database.py", line 130, in insert
    cursor = conn.execute(query, tuple(data.values()))
sqlite3.IntegrityError: UNIQUE constraint failed: settings.key
2025-08-15 19:30:29,034 - data.database - ERROR - database:get_connection:47
Message: Database operation failed: UNIQUE constraint failed: settings.key
Exception: (<class 'sqlite3.IntegrityError'>, IntegrityError('UNIQUE constraint failed: settings.key'), <traceback object at 0x0000019FA25DD840>)
---
Traceback (most recent call last):
  File "C:\Users\nolan\personal\personal-projects\Nabu\data\database.py", line 43, in get_connection
    yield conn
  File "C:\Users\nolan\personal\personal-projects\Nabu\data\database.py", line 130, in insert
    cursor = conn.execute(query, tuple(data.values()))
sqlite3.IntegrityError: UNIQUE constraint failed: settings.key
2025-08-15 19:30:29,049 - data.database - ERROR - database:get_connection:47
Message: Database operation failed: UNIQUE constraint failed: vocabulary.word, vocabulary.language
Exception: (<class 'sqlite3.IntegrityError'>, IntegrityError('UNIQUE constraint failed: vocabulary.word, vocabulary.language'), <traceback object at 0x0000019FA25DD480>)
---
Traceback (most recent call last):
  File "C:\Users\nolan\personal\personal-projects\Nabu\data\database.py", line 43, in get_connection
    yield conn
  File "C:\Users\nolan\personal\personal-projects\Nabu\data\database.py", line 130, in insert
    cursor = conn.execute(query, tuple(data.values()))
sqlite3.IntegrityError: UNIQUE constraint failed: vocabulary.word, vocabulary.language
2025-08-15 19:30:29,056 - data.database - ERROR - database:get_connection:47
Message: Database operation failed: UNIQUE constraint failed: vocabulary.word, vocabulary.language
Exception: (<class 'sqlite3.IntegrityError'>, IntegrityError('UNIQUE constraint failed: vocabulary.word, vocabulary.language'), <traceback object at 0x0000019FA25DD840>)
---
Traceback (most recent call last):
  File "C:\Users\nolan\personal\personal-projects\Nabu\data\database.py", line 43, in get_connection
    yield conn
  File "C:\Users\nolan\personal\personal-projects\Nabu\data\database.py", line 130, in insert
    cursor = conn.execute(query, tuple(data.values()))
sqlite3.IntegrityError: UNIQUE constraint failed: vocabulary.word, vocabulary.language
2025-08-15 19:35:03,480 - data.database - ERROR - database:get_connection:47
Message: Database operation failed: UNIQUE constraint failed: settings.key
Exception: (<class 'sqlite3.IntegrityError'>, IntegrityError('UNIQUE constraint failed: settings.key'), <traceback object at 0x0000026C1FDDD040>)
---
Traceback (most recent call last):
  File "C:\Users\nolan\personal\personal-projects\Nabu\data\database.py", line 43, in get_connection
    yield conn
  File "C:\Users\nolan\personal\personal-projects\Nabu\data\database.py", line 130, in insert
    cursor = conn.execute(query, tuple(data.values()))
sqlite3.IntegrityError: UNIQUE constraint failed: settings.key
2025-08-15 19:35:03,488 - data.database - ERROR - database:get_connection:47
Message: Database operation failed: UNIQUE constraint failed: settings.key
Exception: (<class 'sqlite3.IntegrityError'>, IntegrityError('UNIQUE constraint failed: settings.key'), <traceback object at 0x0000026C1FDDDC40>)
---
Traceback (most recent call last):
  File "C:\Users\nolan\personal\personal-projects\Nabu\data\database.py", line 43, in get_connection
    yield conn
  File "C:\Users\nolan\personal\personal-projects\Nabu\data\database.py", line 130, in insert
    cursor = conn.execute(query, tuple(data.values()))
sqlite3.IntegrityError: UNIQUE constraint failed: settings.key
2025-08-15 19:35:03,495 - data.database - ERROR - database:get_connection:47
Message: Database operation failed: UNIQUE constraint failed: settings.key
Exception: (<class 'sqlite3.IntegrityError'>, IntegrityError('UNIQUE constraint failed: settings.key'), <traceback object at 0x0000026C1FDDDC40>)
---
Traceback (most recent call last):
  File "C:\Users\nolan\personal\personal-projects\Nabu\data\database.py", line 43, in get_connection
    yield conn
  File "C:\Users\nolan\personal\personal-projects\Nabu\data\database.py", line 130, in insert
    cursor = conn.execute(query, tuple(data.values()))
sqlite3.IntegrityError: UNIQUE constraint failed: settings.key
2025-08-15 19:35:03,499 - data.database - ERROR - database:get_connection:47
Message: Database operation failed: UNIQUE constraint failed: settings.key
Exception: (<class 'sqlite3.IntegrityError'>, IntegrityError('UNIQUE constraint failed: settings.key'), <traceback object at 0x0000026C1FDDDC40>)
---
Traceback (most recent call last):
  File "C:\Users\nolan\personal\personal-projects\Nabu\data\database.py", line 43, in get_connection
    yield conn
  File "C:\Users\nolan\personal\personal-projects\Nabu\data\database.py", line 130, in insert
    cursor = conn.execute(query, tuple(data.values()))
sqlite3.IntegrityError: UNIQUE constraint failed: settings.key
2025-08-15 19:35:03,503 - data.database - ERROR - database:get_connection:47
Message: Database operation failed: UNIQUE constraint failed: settings.key
Exception: (<class 'sqlite3.IntegrityError'>, IntegrityError('UNIQUE constraint failed: settings.key'), <traceback object at 0x0000026C1FDDDC40>)
---
Traceback (most recent call last):
  File "C:\Users\nolan\personal\personal-projects\Nabu\data\database.py", line 43, in get_connection
    yield conn
  File "C:\Users\nolan\personal\personal-projects\Nabu\data\database.py", line 130, in insert
    cursor = conn.execute(query, tuple(data.values()))
sqlite3.IntegrityError: UNIQUE constraint failed: settings.key
2025-08-15 19:35:03,514 - data.database - ERROR - database:get_connection:47
Message: Database operation failed: UNIQUE constraint failed: settings.key
Exception: (<class 'sqlite3.IntegrityError'>, IntegrityError('UNIQUE constraint failed: settings.key'), <traceback object at 0x0000026C1FDDDC40>)
---
Traceback (most recent call last):
  File "C:\Users\nolan\personal\personal-projects\Nabu\data\database.py", line 43, in get_connection
    yield conn
  File "C:\Users\nolan\personal\personal-projects\Nabu\data\database.py", line 130, in insert
    cursor = conn.execute(query, tuple(data.values()))
sqlite3.IntegrityError: UNIQUE constraint failed: settings.key
2025-08-15 19:35:03,519 - data.database - ERROR - database:get_connection:47
Message: Database operation failed: UNIQUE constraint failed: settings.key
Exception: (<class 'sqlite3.IntegrityError'>, IntegrityError('UNIQUE constraint failed: settings.key'), <traceback object at 0x0000026C1FDDDC40>)
---
Traceback (most recent call last):
  File "C:\Users\nolan\personal\personal-projects\Nabu\data\database.py", line 43, in get_connection
    yield conn
  File "C:\Users\nolan\personal\personal-projects\Nabu\data\database.py", line 130, in insert
    cursor = conn.execute(query, tuple(data.values()))
sqlite3.IntegrityError: UNIQUE constraint failed: settings.key
2025-08-15 19:35:03,524 - data.database - ERROR - database:get_connection:47
Message: Database operation failed: UNIQUE constraint failed: settings.key
Exception: (<class 'sqlite3.IntegrityError'>, IntegrityError('UNIQUE constraint failed: settings.key'), <traceback object at 0x0000026C1FDDDC40>)
---
Traceback (most recent call last):
  File "C:\Users\nolan\personal\personal-projects\Nabu\data\database.py", line 43, in get_connection
    yield conn
  File "C:\Users\nolan\personal\personal-projects\Nabu\data\database.py", line 130, in insert
    cursor = conn.execute(query, tuple(data.values()))
sqlite3.IntegrityError: UNIQUE constraint failed: settings.key
2025-08-15 19:35:03,532 - data.database - ERROR - database:get_connection:47
Message: Database operation failed: UNIQUE constraint failed: settings.key
Exception: (<class 'sqlite3.IntegrityError'>, IntegrityError('UNIQUE constraint failed: settings.key'), <traceback object at 0x0000026C1FDDDC40>)
---
Traceback (most recent call last):
  File "C:\Users\nolan\personal\personal-projects\Nabu\data\database.py", line 43, in get_connection
    yield conn
  File "C:\Users\nolan\personal\personal-projects\Nabu\data\database.py", line 130, in insert
    cursor = conn.execute(query, tuple(data.values()))
sqlite3.IntegrityError: UNIQUE constraint failed: settings.key
2025-08-15 19:35:03,532 - data.database - ERROR - database:get_connection:47
Message: Database operation failed: UNIQUE constraint failed: settings.key
Exception: (<class 'sqlite3.IntegrityError'>, IntegrityError('UNIQUE constraint failed: settings.key'), <traceback object at 0x0000026C1FDDDC40>)
---
Traceback (most recent call last):
  File "C:\Users\nolan\personal\personal-projects\Nabu\data\database.py", line 43, in get_connection
    yield conn
  File "C:\Users\nolan\personal\personal-projects\Nabu\data\database.py", line 130, in insert
    cursor = conn.execute(query, tuple(data.values()))
sqlite3.IntegrityError: UNIQUE constraint failed: settings.key
2025-08-15 19:35:03,553 - data.database - ERROR - database:get_connection:47
Message: Database operation failed: UNIQUE constraint failed: vocabulary.word, vocabulary.language
Exception: (<class 'sqlite3.IntegrityError'>, IntegrityError('UNIQUE constraint failed: vocabulary.word, vocabulary.language'), <traceback object at 0x0000026C1FDDDC40>)
---
Traceback (most recent call last):
  File "C:\Users\nolan\personal\personal-projects\Nabu\data\database.py", line 43, in get_connection
    yield conn
  File "C:\Users\nolan\personal\personal-projects\Nabu\data\database.py", line 130, in insert
    cursor = conn.execute(query, tuple(data.values()))
sqlite3.IntegrityError: UNIQUE constraint failed: vocabulary.word, vocabulary.language
2025-08-15 19:35:03,560 - data.database - ERROR - database:get_connection:47
Message: Database operation failed: UNIQUE constraint failed: vocabulary.word, vocabulary.language
Exception: (<class 'sqlite3.IntegrityError'>, IntegrityError('UNIQUE constraint failed: vocabulary.word, vocabulary.language'), <traceback object at 0x0000026C1FDDDC40>)
---
Traceback (most recent call last):
  File "C:\Users\nolan\personal\personal-projects\Nabu\data\database.py", line 43, in get_connection
    yield conn
  File "C:\Users\nolan\personal\personal-projects\Nabu\data\database.py", line 130, in insert
    cursor = conn.execute(query, tuple(data.values()))
sqlite3.IntegrityError: UNIQUE constraint failed: vocabulary.word, vocabulary.language
2025-08-15 19:35:34,180 - core.event_bus - ERROR - event_bus:publish:69
Message: Error in event callback for tts_completed: main thread is not in main loop
Exception: (<class 'RuntimeError'>, RuntimeError('main thread is not in main loop'), <traceback object at 0x0000026C23D57640>)
---
Traceback (most recent call last):
  File "C:\Users\nolan\personal\personal-projects\Nabu\core\event_bus.py", line 67, in publish
    callback(data)
  File "C:\Users\nolan\personal\personal-projects\Nabu\ui\conversation.py", line 281, in _on_tts_completed
    self.status_label.config(text="Ready for next input")
  File "C:\Users\nolan\Anaconda3\lib\tkinter\__init__.py", line 1646, in configure
    return self._configure('configure', cnf, kw)
  File "C:\Users\nolan\Anaconda3\lib\tkinter\__init__.py", line 1636, in _configure
    self.tk.call(_flatten((self._w, cmd)) + self._options(cnf))
RuntimeError: main thread is not in main loop
2025-08-15 19:38:11,310 - data.database - ERROR - database:get_connection:47
Message: Database operation failed: UNIQUE constraint failed: settings.key
Exception: (<class 'sqlite3.IntegrityError'>, IntegrityError('UNIQUE constraint failed: settings.key'), <traceback object at 0x00000167D824C840>)
---
Traceback (most recent call last):
  File "C:\Users\nolan\personal\personal-projects\Nabu\data\database.py", line 43, in get_connection
    yield conn
  File "C:\Users\nolan\personal\personal-projects\Nabu\data\database.py", line 130, in insert
    cursor = conn.execute(query, tuple(data.values()))
sqlite3.IntegrityError: UNIQUE constraint failed: settings.key
2025-08-15 19:38:11,316 - data.database - ERROR - database:get_connection:47
Message: Database operation failed: UNIQUE constraint failed: settings.key
Exception: (<class 'sqlite3.IntegrityError'>, IntegrityError('UNIQUE constraint failed: settings.key'), <traceback object at 0x00000167D824C8C0>)
---
Traceback (most recent call last):
  File "C:\Users\nolan\personal\personal-projects\Nabu\data\database.py", line 43, in get_connection
    yield conn
  File "C:\Users\nolan\personal\personal-projects\Nabu\data\database.py", line 130, in insert
    cursor = conn.execute(query, tuple(data.values()))
sqlite3.IntegrityError: UNIQUE constraint failed: settings.key
2025-08-15 19:38:11,322 - data.database - ERROR - database:get_connection:47
Message: Database operation failed: UNIQUE constraint failed: settings.key
Exception: (<class 'sqlite3.IntegrityError'>, IntegrityError('UNIQUE constraint failed: settings.key'), <traceback object at 0x00000167D824C840>)
---
Traceback (most recent call last):
  File "C:\Users\nolan\personal\personal-projects\Nabu\data\database.py", line 43, in get_connection
    yield conn
  File "C:\Users\nolan\personal\personal-projects\Nabu\data\database.py", line 130, in insert
    cursor = conn.execute(query, tuple(data.values()))
sqlite3.IntegrityError: UNIQUE constraint failed: settings.key
2025-08-15 19:38:11,328 - data.database - ERROR - database:get_connection:47
Message: Database operation failed: UNIQUE constraint failed: settings.key
Exception: (<class 'sqlite3.IntegrityError'>, IntegrityError('UNIQUE constraint failed: settings.key'), <traceback object at 0x00000167D824C8C0>)
---
Traceback (most recent call last):
  File "C:\Users\nolan\personal\personal-projects\Nabu\data\database.py", line 43, in get_connection
    yield conn
  File "C:\Users\nolan\personal\personal-projects\Nabu\data\database.py", line 130, in insert
    cursor = conn.execute(query, tuple(data.values()))
sqlite3.IntegrityError: UNIQUE constraint failed: settings.key
2025-08-15 19:38:11,334 - data.database - ERROR - database:get_connection:47
Message: Database operation failed: UNIQUE constraint failed: settings.key
Exception: (<class 'sqlite3.IntegrityError'>, IntegrityError('UNIQUE constraint failed: settings.key'), <traceback object at 0x00000167D824C840>)
---
Traceback (most recent call last):
  File "C:\Users\nolan\personal\personal-projects\Nabu\data\database.py", line 43, in get_connection
    yield conn
  File "C:\Users\nolan\personal\personal-projects\Nabu\data\database.py", line 130, in insert
    cursor = conn.execute(query, tuple(data.values()))
sqlite3.IntegrityError: UNIQUE constraint failed: settings.key
2025-08-15 19:38:11,339 - data.database - ERROR - database:get_connection:47
Message: Database operation failed: UNIQUE constraint failed: settings.key
Exception: (<class 'sqlite3.IntegrityError'>, IntegrityError('UNIQUE constraint failed: settings.key'), <traceback object at 0x00000167D824C8C0>)
---
Traceback (most recent call last):
  File "C:\Users\nolan\personal\personal-projects\Nabu\data\database.py", line 43, in get_connection
    yield conn
  File "C:\Users\nolan\personal\personal-projects\Nabu\data\database.py", line 130, in insert
    cursor = conn.execute(query, tuple(data.values()))
sqlite3.IntegrityError: UNIQUE constraint failed: settings.key
2025-08-15 19:38:11,345 - data.database - ERROR - database:get_connection:47
Message: Database operation failed: UNIQUE constraint failed: settings.key
Exception: (<class 'sqlite3.IntegrityError'>, IntegrityError('UNIQUE constraint failed: settings.key'), <traceback object at 0x00000167D824C840>)
---
Traceback (most recent call last):
  File "C:\Users\nolan\personal\personal-projects\Nabu\data\database.py", line 43, in get_connection
    yield conn
  File "C:\Users\nolan\personal\personal-projects\Nabu\data\database.py", line 130, in insert
    cursor = conn.execute(query, tuple(data.values()))
sqlite3.IntegrityError: UNIQUE constraint failed: settings.key
2025-08-15 19:38:11,352 - data.database - ERROR - database:get_connection:47
Message: Database operation failed: UNIQUE constraint failed: settings.key
Exception: (<class 'sqlite3.IntegrityError'>, IntegrityError('UNIQUE constraint failed: settings.key'), <traceback object at 0x00000167D824C8C0>)
---
Traceback (most recent call last):
  File "C:\Users\nolan\personal\personal-projects\Nabu\data\database.py", line 43, in get_connection
    yield conn
  File "C:\Users\nolan\personal\personal-projects\Nabu\data\database.py", line 130, in insert
    cursor = conn.execute(query, tuple(data.values()))
sqlite3.IntegrityError: UNIQUE constraint failed: settings.key
2025-08-15 19:38:11,358 - data.database - ERROR - database:get_connection:47
Message: Database operation failed: UNIQUE constraint failed: settings.key
Exception: (<class 'sqlite3.IntegrityError'>, IntegrityError('UNIQUE constraint failed: settings.key'), <traceback object at 0x00000167D824C840>)
---
Traceback (most recent call last):
  File "C:\Users\nolan\personal\personal-projects\Nabu\data\database.py", line 43, in get_connection
    yield conn
  File "C:\Users\nolan\personal\personal-projects\Nabu\data\database.py", line 130, in insert
    cursor = conn.execute(query, tuple(data.values()))
sqlite3.IntegrityError: UNIQUE constraint failed: settings.key
2025-08-15 19:38:11,360 - data.database - ERROR - database:get_connection:47
Message: Database operation failed: UNIQUE constraint failed: settings.key
Exception: (<class 'sqlite3.IntegrityError'>, IntegrityError('UNIQUE constraint failed: settings.key'), <traceback object at 0x00000167D824C8C0>)
---
Traceback (most recent call last):
  File "C:\Users\nolan\personal\personal-projects\Nabu\data\database.py", line 43, in get_connection
    yield conn
  File "C:\Users\nolan\personal\personal-projects\Nabu\data\database.py", line 130, in insert
    cursor = conn.execute(query, tuple(data.values()))
sqlite3.IntegrityError: UNIQUE constraint failed: settings.key
2025-08-15 19:38:11,386 - data.database - ERROR - database:get_connection:47
Message: Database operation failed: UNIQUE constraint failed: vocabulary.word, vocabulary.language
Exception: (<class 'sqlite3.IntegrityError'>, IntegrityError('UNIQUE constraint failed: vocabulary.word, vocabulary.language'), <traceback object at 0x00000167D824C840>)
---
Traceback (most recent call last):
  File "C:\Users\nolan\personal\personal-projects\Nabu\data\database.py", line 43, in get_connection
    yield conn
  File "C:\Users\nolan\personal\personal-projects\Nabu\data\database.py", line 130, in insert
    cursor = conn.execute(query, tuple(data.values()))
sqlite3.IntegrityError: UNIQUE constraint failed: vocabulary.word, vocabulary.language
2025-08-15 19:38:11,394 - data.database - ERROR - database:get_connection:47
Message: Database operation failed: UNIQUE constraint failed: vocabulary.word, vocabulary.language
Exception: (<class 'sqlite3.IntegrityError'>, IntegrityError('UNIQUE constraint failed: vocabulary.word, vocabulary.language'), <traceback object at 0x00000167D824C8C0>)
---
Traceback (most recent call last):
  File "C:\Users\nolan\personal\personal-projects\Nabu\data\database.py", line 43, in get_connection
    yield conn
  File "C:\Users\nolan\personal\personal-projects\Nabu\data\database.py", line 130, in insert
    cursor = conn.execute(query, tuple(data.values()))
sqlite3.IntegrityError: UNIQUE constraint failed: vocabulary.word, vocabulary.language
2025-08-15 19:38:13,092 - __main__ - ERROR - main:main:68
Message: Application crashed: 'ConversationFrame' object has no attribute 'grid_remove'
Exception: (<class 'AttributeError'>, AttributeError("'ConversationFrame' object has no attribute 'grid_remove'"), <traceback object at 0x00000167D821FA80>)
---
Traceback (most recent call last):
  File "C:\Users\nolan\personal\personal-projects\Nabu\main.py", line 59, in main
    app = TutorApplication()
  File "C:\Users\nolan\personal\personal-projects\Nabu\core\application.py", line 45, in __init__
    self._initialize_ui()
  File "C:\Users\nolan\personal\personal-projects\Nabu\core\application.py", line 98, in _initialize_ui
    self.conversation_frame.grid_remove()
AttributeError: 'ConversationFrame' object has no attribute 'grid_remove'
2025-08-15 19:38:34,789 - data.database - ERROR - database:get_connection:47
Message: Database operation failed: UNIQUE constraint failed: settings.key
Exception: (<class 'sqlite3.IntegrityError'>, IntegrityError('UNIQUE constraint failed: settings.key'), <traceback object at 0x000002BD3AA0BEC0>)
---
Traceback (most recent call last):
  File "C:\Users\nolan\personal\personal-projects\Nabu\data\database.py", line 43, in get_connection
    yield conn
  File "C:\Users\nolan\personal\personal-projects\Nabu\data\database.py", line 130, in insert
    cursor = conn.execute(query, tuple(data.values()))
sqlite3.IntegrityError: UNIQUE constraint failed: settings.key
2025-08-15 19:38:34,800 - data.database - ERROR - database:get_connection:47
Message: Database operation failed: UNIQUE constraint failed: settings.key
Exception: (<class 'sqlite3.IntegrityError'>, IntegrityError('UNIQUE constraint failed: settings.key'), <traceback object at 0x000002BD3AA0BD40>)
---
Traceback (most recent call last):
  File "C:\Users\nolan\personal\personal-projects\Nabu\data\database.py", line 43, in get_connection
    yield conn
  File "C:\Users\nolan\personal\personal-projects\Nabu\data\database.py", line 130, in insert
    cursor = conn.execute(query, tuple(data.values()))
sqlite3.IntegrityError: UNIQUE constraint failed: settings.key
2025-08-15 19:38:34,807 - data.database - ERROR - database:get_connection:47
Message: Database operation failed: UNIQUE constraint failed: settings.key
Exception: (<class 'sqlite3.IntegrityError'>, IntegrityError('UNIQUE constraint failed: settings.key'), <traceback object at 0x000002BD3AA0BEC0>)
---
Traceback (most recent call last):
  File "C:\Users\nolan\personal\personal-projects\Nabu\data\database.py", line 43, in get_connection
    yield conn
  File "C:\Users\nolan\personal\personal-projects\Nabu\data\database.py", line 130, in insert
    cursor = conn.execute(query, tuple(data.values()))
sqlite3.IntegrityError: UNIQUE constraint failed: settings.key
2025-08-15 19:38:34,812 - data.database - ERROR - database:get_connection:47
Message: Database operation failed: UNIQUE constraint failed: settings.key
Exception: (<class 'sqlite3.IntegrityError'>, IntegrityError('UNIQUE constraint failed: settings.key'), <traceback object at 0x000002BD3AA0BD40>)
---
Traceback (most recent call last):
  File "C:\Users\nolan\personal\personal-projects\Nabu\data\database.py", line 43, in get_connection
    yield conn
  File "C:\Users\nolan\personal\personal-projects\Nabu\data\database.py", line 130, in insert
    cursor = conn.execute(query, tuple(data.values()))
sqlite3.IntegrityError: UNIQUE constraint failed: settings.key
2025-08-15 19:38:34,819 - data.database - ERROR - database:get_connection:47
Message: Database operation failed: UNIQUE constraint failed: settings.key
Exception: (<class 'sqlite3.IntegrityError'>, IntegrityError('UNIQUE constraint failed: settings.key'), <traceback object at 0x000002BD3AA0BEC0>)
---
Traceback (most recent call last):
  File "C:\Users\nolan\personal\personal-projects\Nabu\data\database.py", line 43, in get_connection
    yield conn
  File "C:\Users\nolan\personal\personal-projects\Nabu\data\database.py", line 130, in insert
    cursor = conn.execute(query, tuple(data.values()))
sqlite3.IntegrityError: UNIQUE constraint failed: settings.key
2025-08-15 19:38:34,825 - data.database - ERROR - database:get_connection:47
Message: Database operation failed: UNIQUE constraint failed: settings.key
Exception: (<class 'sqlite3.IntegrityError'>, IntegrityError('UNIQUE constraint failed: settings.key'), <traceback object at 0x000002BD3AA0BD40>)
---
Traceback (most recent call last):
  File "C:\Users\nolan\personal\personal-projects\Nabu\data\database.py", line 43, in get_connection
    yield conn
  File "C:\Users\nolan\personal\personal-projects\Nabu\data\database.py", line 130, in insert
    cursor = conn.execute(query, tuple(data.values()))
sqlite3.IntegrityError: UNIQUE constraint failed: settings.key
2025-08-15 19:38:34,828 - data.database - ERROR - database:get_connection:47
Message: Database operation failed: UNIQUE constraint failed: settings.key
Exception: (<class 'sqlite3.IntegrityError'>, IntegrityError('UNIQUE constraint failed: settings.key'), <traceback object at 0x000002BD3AA0BEC0>)
---
Traceback (most recent call last):
  File "C:\Users\nolan\personal\personal-projects\Nabu\data\database.py", line 43, in get_connection
    yield conn
  File "C:\Users\nolan\personal\personal-projects\Nabu\data\database.py", line 130, in insert
    cursor = conn.execute(query, tuple(data.values()))
sqlite3.IntegrityError: UNIQUE constraint failed: settings.key
2025-08-15 19:38:34,836 - data.database - ERROR - database:get_connection:47
Message: Database operation failed: UNIQUE constraint failed: settings.key
Exception: (<class 'sqlite3.IntegrityError'>, IntegrityError('UNIQUE constraint failed: settings.key'), <traceback object at 0x000002BD3AA0BD40>)
---
Traceback (most recent call last):
  File "C:\Users\nolan\personal\personal-projects\Nabu\data\database.py", line 43, in get_connection
    yield conn
  File "C:\Users\nolan\personal\personal-projects\Nabu\data\database.py", line 130, in insert
    cursor = conn.execute(query, tuple(data.values()))
sqlite3.IntegrityError: UNIQUE constraint failed: settings.key
2025-08-15 19:38:34,843 - data.database - ERROR - database:get_connection:47
Message: Database operation failed: UNIQUE constraint failed: settings.key
Exception: (<class 'sqlite3.IntegrityError'>, IntegrityError('UNIQUE constraint failed: settings.key'), <traceback object at 0x000002BD3AA0BEC0>)
---
Traceback (most recent call last):
  File "C:\Users\nolan\personal\personal-projects\Nabu\data\database.py", line 43, in get_connection
    yield conn
  File "C:\Users\nolan\personal\personal-projects\Nabu\data\database.py", line 130, in insert
    cursor = conn.execute(query, tuple(data.values()))
sqlite3.IntegrityError: UNIQUE constraint failed: settings.key
2025-08-15 19:38:34,846 - data.database - ERROR - database:get_connection:47
Message: Database operation failed: UNIQUE constraint failed: settings.key
Exception: (<class 'sqlite3.IntegrityError'>, IntegrityError('UNIQUE constraint failed: settings.key'), <traceback object at 0x000002BD3AA0BD40>)
---
Traceback (most recent call last):
  File "C:\Users\nolan\personal\personal-projects\Nabu\data\database.py", line 43, in get_connection
    yield conn
  File "C:\Users\nolan\personal\personal-projects\Nabu\data\database.py", line 130, in insert
    cursor = conn.execute(query, tuple(data.values()))
sqlite3.IntegrityError: UNIQUE constraint failed: settings.key
2025-08-15 19:38:34,914 - data.database - ERROR - database:get_connection:47
Message: Database operation failed: UNIQUE constraint failed: vocabulary.word, vocabulary.language
Exception: (<class 'sqlite3.IntegrityError'>, IntegrityError('UNIQUE constraint failed: vocabulary.word, vocabulary.language'), <traceback object at 0x000002BD3AA0BEC0>)
---
Traceback (most recent call last):
  File "C:\Users\nolan\personal\personal-projects\Nabu\data\database.py", line 43, in get_connection
    yield conn
  File "C:\Users\nolan\personal\personal-projects\Nabu\data\database.py", line 130, in insert
    cursor = conn.execute(query, tuple(data.values()))
sqlite3.IntegrityError: UNIQUE constraint failed: vocabulary.word, vocabulary.language
2025-08-15 19:38:34,928 - data.database - ERROR - database:get_connection:47
Message: Database operation failed: UNIQUE constraint failed: vocabulary.word, vocabulary.language
Exception: (<class 'sqlite3.IntegrityError'>, IntegrityError('UNIQUE constraint failed: vocabulary.word, vocabulary.language'), <traceback object at 0x000002BD3AA0BD40>)
---
Traceback (most recent call last):
  File "C:\Users\nolan\personal\personal-projects\Nabu\data\database.py", line 43, in get_connection
    yield conn
  File "C:\Users\nolan\personal\personal-projects\Nabu\data\database.py", line 130, in insert
    cursor = conn.execute(query, tuple(data.values()))
sqlite3.IntegrityError: UNIQUE constraint failed: vocabulary.word, vocabulary.language
2025-08-15 19:42:34,479 - data.database - ERROR - database:get_connection:47
Message: Database operation failed: UNIQUE constraint failed: settings.key
Exception: (<class 'sqlite3.IntegrityError'>, IntegrityError('UNIQUE constraint failed: settings.key'), <traceback object at 0x000002797130AE00>)
---
Traceback (most recent call last):
  File "C:\Users\nolan\personal\personal-projects\Nabu\data\database.py", line 43, in get_connection
    yield conn
  File "C:\Users\nolan\personal\personal-projects\Nabu\data\database.py", line 130, in insert
    cursor = conn.execute(query, tuple(data.values()))
sqlite3.IntegrityError: UNIQUE constraint failed: settings.key
2025-08-15 19:42:34,490 - data.database - ERROR - database:get_connection:47
Message: Database operation failed: UNIQUE constraint failed: settings.key
Exception: (<class 'sqlite3.IntegrityError'>, IntegrityError('UNIQUE constraint failed: settings.key'), <traceback object at 0x000002797130AE80>)
---
Traceback (most recent call last):
  File "C:\Users\nolan\personal\personal-projects\Nabu\data\database.py", line 43, in get_connection
    yield conn
  File "C:\Users\nolan\personal\personal-projects\Nabu\data\database.py", line 130, in insert
    cursor = conn.execute(query, tuple(data.values()))
sqlite3.IntegrityError: UNIQUE constraint failed: settings.key
2025-08-15 19:42:34,490 - data.database - ERROR - database:get_connection:47
Message: Database operation failed: UNIQUE constraint failed: settings.key
Exception: (<class 'sqlite3.IntegrityError'>, IntegrityError('UNIQUE constraint failed: settings.key'), <traceback object at 0x000002797130AE00>)
---
Traceback (most recent call last):
  File "C:\Users\nolan\personal\personal-projects\Nabu\data\database.py", line 43, in get_connection
    yield conn
  File "C:\Users\nolan\personal\personal-projects\Nabu\data\database.py", line 130, in insert
    cursor = conn.execute(query, tuple(data.values()))
sqlite3.IntegrityError: UNIQUE constraint failed: settings.key
2025-08-15 19:42:34,503 - data.database - ERROR - database:get_connection:47
Message: Database operation failed: UNIQUE constraint failed: settings.key
Exception: (<class 'sqlite3.IntegrityError'>, IntegrityError('UNIQUE constraint failed: settings.key'), <traceback object at 0x000002797130AE80>)
---
Traceback (most recent call last):
  File "C:\Users\nolan\personal\personal-projects\Nabu\data\database.py", line 43, in get_connection
    yield conn
  File "C:\Users\nolan\personal\personal-projects\Nabu\data\database.py", line 130, in insert
    cursor = conn.execute(query, tuple(data.values()))
sqlite3.IntegrityError: UNIQUE constraint failed: settings.key
2025-08-15 19:42:34,506 - data.database - ERROR - database:get_connection:47
Message: Database operation failed: UNIQUE constraint failed: settings.key
Exception: (<class 'sqlite3.IntegrityError'>, IntegrityError('UNIQUE constraint failed: settings.key'), <traceback object at 0x000002797130AE00>)
---
Traceback (most recent call last):
  File "C:\Users\nolan\personal\personal-projects\Nabu\data\database.py", line 43, in get_connection
    yield conn
  File "C:\Users\nolan\personal\personal-projects\Nabu\data\database.py", line 130, in insert
    cursor = conn.execute(query, tuple(data.values()))
sqlite3.IntegrityError: UNIQUE constraint failed: settings.key
2025-08-15 19:42:34,516 - data.database - ERROR - database:get_connection:47
Message: Database operation failed: UNIQUE constraint failed: settings.key
Exception: (<class 'sqlite3.IntegrityError'>, IntegrityError('UNIQUE constraint failed: settings.key'), <traceback object at 0x000002797130AE80>)
---
Traceback (most recent call last):
  File "C:\Users\nolan\personal\personal-projects\Nabu\data\database.py", line 43, in get_connection
    yield conn
  File "C:\Users\nolan\personal\personal-projects\Nabu\data\database.py", line 130, in insert
    cursor = conn.execute(query, tuple(data.values()))
sqlite3.IntegrityError: UNIQUE constraint failed: settings.key
2025-08-15 19:42:34,523 - data.database - ERROR - database:get_connection:47
Message: Database operation failed: UNIQUE constraint failed: settings.key
Exception: (<class 'sqlite3.IntegrityError'>, IntegrityError('UNIQUE constraint failed: settings.key'), <traceback object at 0x000002797130AE00>)
---
Traceback (most recent call last):
  File "C:\Users\nolan\personal\personal-projects\Nabu\data\database.py", line 43, in get_connection
    yield conn
  File "C:\Users\nolan\personal\personal-projects\Nabu\data\database.py", line 130, in insert
    cursor = conn.execute(query, tuple(data.values()))
sqlite3.IntegrityError: UNIQUE constraint failed: settings.key
2025-08-15 19:42:34,523 - data.database - ERROR - database:get_connection:47
Message: Database operation failed: UNIQUE constraint failed: settings.key
Exception: (<class 'sqlite3.IntegrityError'>, IntegrityError('UNIQUE constraint failed: settings.key'), <traceback object at 0x000002797130AE80>)
---
Traceback (most recent call last):
  File "C:\Users\nolan\personal\personal-projects\Nabu\data\database.py", line 43, in get_connection
    yield conn
  File "C:\Users\nolan\personal\personal-projects\Nabu\data\database.py", line 130, in insert
    cursor = conn.execute(query, tuple(data.values()))
sqlite3.IntegrityError: UNIQUE constraint failed: settings.key
2025-08-15 19:42:34,536 - data.database - ERROR - database:get_connection:47
Message: Database operation failed: UNIQUE constraint failed: settings.key
Exception: (<class 'sqlite3.IntegrityError'>, IntegrityError('UNIQUE constraint failed: settings.key'), <traceback object at 0x000002797130AE00>)
---
Traceback (most recent call last):
  File "C:\Users\nolan\personal\personal-projects\Nabu\data\database.py", line 43, in get_connection
    yield conn
  File "C:\Users\nolan\personal\personal-projects\Nabu\data\database.py", line 130, in insert
    cursor = conn.execute(query, tuple(data.values()))
sqlite3.IntegrityError: UNIQUE constraint failed: settings.key
2025-08-15 19:42:34,542 - data.database - ERROR - database:get_connection:47
Message: Database operation failed: UNIQUE constraint failed: settings.key
Exception: (<class 'sqlite3.IntegrityError'>, IntegrityError('UNIQUE constraint failed: settings.key'), <traceback object at 0x000002797130AE80>)
---
Traceback (most recent call last):
  File "C:\Users\nolan\personal\personal-projects\Nabu\data\database.py", line 43, in get_connection
    yield conn
  File "C:\Users\nolan\personal\personal-projects\Nabu\data\database.py", line 130, in insert
    cursor = conn.execute(query, tuple(data.values()))
sqlite3.IntegrityError: UNIQUE constraint failed: settings.key
2025-08-15 19:42:34,556 - data.database - ERROR - database:get_connection:47
Message: Database operation failed: UNIQUE constraint failed: vocabulary.word, vocabulary.language
Exception: (<class 'sqlite3.IntegrityError'>, IntegrityError('UNIQUE constraint failed: vocabulary.word, vocabulary.language'), <traceback object at 0x000002797130AE00>)
---
Traceback (most recent call last):
  File "C:\Users\nolan\personal\personal-projects\Nabu\data\database.py", line 43, in get_connection
    yield conn
  File "C:\Users\nolan\personal\personal-projects\Nabu\data\database.py", line 130, in insert
    cursor = conn.execute(query, tuple(data.values()))
sqlite3.IntegrityError: UNIQUE constraint failed: vocabulary.word, vocabulary.language
2025-08-15 19:42:34,571 - data.database - ERROR - database:get_connection:47
Message: Database operation failed: UNIQUE constraint failed: vocabulary.word, vocabulary.language
Exception: (<class 'sqlite3.IntegrityError'>, IntegrityError('UNIQUE constraint failed: vocabulary.word, vocabulary.language'), <traceback object at 0x000002797130AE80>)
---
Traceback (most recent call last):
  File "C:\Users\nolan\personal\personal-projects\Nabu\data\database.py", line 43, in get_connection
    yield conn
  File "C:\Users\nolan\personal\personal-projects\Nabu\data\database.py", line 130, in insert
    cursor = conn.execute(query, tuple(data.values()))
sqlite3.IntegrityError: UNIQUE constraint failed: vocabulary.word, vocabulary.language
2025-08-15 19:44:34,589 - data.database - ERROR - database:get_connection:47
Message: Database operation failed: UNIQUE constraint failed: settings.key
Exception: (<class 'sqlite3.IntegrityError'>, IntegrityError('UNIQUE constraint failed: settings.key'), <traceback object at 0x00000245702BBE40>)
---
Traceback (most recent call last):
  File "C:\Users\nolan\personal\personal-projects\Nabu\data\database.py", line 43, in get_connection
    yield conn
  File "C:\Users\nolan\personal\personal-projects\Nabu\data\database.py", line 130, in insert
    cursor = conn.execute(query, tuple(data.values()))
sqlite3.IntegrityError: UNIQUE constraint failed: settings.key
2025-08-15 19:44:34,594 - data.database - ERROR - database:get_connection:47
Message: Database operation failed: UNIQUE constraint failed: settings.key
Exception: (<class 'sqlite3.IntegrityError'>, IntegrityError('UNIQUE constraint failed: settings.key'), <traceback object at 0x00000245702BBC80>)
---
Traceback (most recent call last):
  File "C:\Users\nolan\personal\personal-projects\Nabu\data\database.py", line 43, in get_connection
    yield conn
  File "C:\Users\nolan\personal\personal-projects\Nabu\data\database.py", line 130, in insert
    cursor = conn.execute(query, tuple(data.values()))
sqlite3.IntegrityError: UNIQUE constraint failed: settings.key
2025-08-15 19:44:34,600 - data.database - ERROR - database:get_connection:47
Message: Database operation failed: UNIQUE constraint failed: settings.key
Exception: (<class 'sqlite3.IntegrityError'>, IntegrityError('UNIQUE constraint failed: settings.key'), <traceback object at 0x00000245702BBA00>)
---
Traceback (most recent call last):
  File "C:\Users\nolan\personal\personal-projects\Nabu\data\database.py", line 43, in get_connection
    yield conn
  File "C:\Users\nolan\personal\personal-projects\Nabu\data\database.py", line 130, in insert
    cursor = conn.execute(query, tuple(data.values()))
sqlite3.IntegrityError: UNIQUE constraint failed: settings.key
2025-08-15 19:44:34,608 - data.database - ERROR - database:get_connection:47
Message: Database operation failed: UNIQUE constraint failed: settings.key
Exception: (<class 'sqlite3.IntegrityError'>, IntegrityError('UNIQUE constraint failed: settings.key'), <traceback object at 0x00000245702BBC80>)
---
Traceback (most recent call last):
  File "C:\Users\nolan\personal\personal-projects\Nabu\data\database.py", line 43, in get_connection
    yield conn
  File "C:\Users\nolan\personal\personal-projects\Nabu\data\database.py", line 130, in insert
    cursor = conn.execute(query, tuple(data.values()))
sqlite3.IntegrityError: UNIQUE constraint failed: settings.key
2025-08-15 19:44:34,615 - data.database - ERROR - database:get_connection:47
Message: Database operation failed: UNIQUE constraint failed: settings.key
Exception: (<class 'sqlite3.IntegrityError'>, IntegrityError('UNIQUE constraint failed: settings.key'), <traceback object at 0x00000245702BBA00>)
---
Traceback (most recent call last):
  File "C:\Users\nolan\personal\personal-projects\Nabu\data\database.py", line 43, in get_connection
    yield conn
  File "C:\Users\nolan\personal\personal-projects\Nabu\data\database.py", line 130, in insert
    cursor = conn.execute(query, tuple(data.values()))
sqlite3.IntegrityError: UNIQUE constraint failed: settings.key
2025-08-15 19:44:34,624 - data.database - ERROR - database:get_connection:47
Message: Database operation failed: UNIQUE constraint failed: settings.key
Exception: (<class 'sqlite3.IntegrityError'>, IntegrityError('UNIQUE constraint failed: settings.key'), <traceback object at 0x00000245702BBC80>)
---
Traceback (most recent call last):
  File "C:\Users\nolan\personal\personal-projects\Nabu\data\database.py", line 43, in get_connection
    yield conn
  File "C:\Users\nolan\personal\personal-projects\Nabu\data\database.py", line 130, in insert
    cursor = conn.execute(query, tuple(data.values()))
sqlite3.IntegrityError: UNIQUE constraint failed: settings.key
2025-08-15 19:44:34,631 - data.database - ERROR - database:get_connection:47
Message: Database operation failed: UNIQUE constraint failed: settings.key
Exception: (<class 'sqlite3.IntegrityError'>, IntegrityError('UNIQUE constraint failed: settings.key'), <traceback object at 0x00000245702BBA00>)
---
Traceback (most recent call last):
  File "C:\Users\nolan\personal\personal-projects\Nabu\data\database.py", line 43, in get_connection
    yield conn
  File "C:\Users\nolan\personal\personal-projects\Nabu\data\database.py", line 130, in insert
    cursor = conn.execute(query, tuple(data.values()))
sqlite3.IntegrityError: UNIQUE constraint failed: settings.key
2025-08-15 19:44:34,641 - data.database - ERROR - database:get_connection:47
Message: Database operation failed: UNIQUE constraint failed: settings.key
Exception: (<class 'sqlite3.IntegrityError'>, IntegrityError('UNIQUE constraint failed: settings.key'), <traceback object at 0x00000245702BBC80>)
---
Traceback (most recent call last):
  File "C:\Users\nolan\personal\personal-projects\Nabu\data\database.py", line 43, in get_connection
    yield conn
  File "C:\Users\nolan\personal\personal-projects\Nabu\data\database.py", line 130, in insert
    cursor = conn.execute(query, tuple(data.values()))
sqlite3.IntegrityError: UNIQUE constraint failed: settings.key
2025-08-15 19:44:34,643 - data.database - ERROR - database:get_connection:47
Message: Database operation failed: UNIQUE constraint failed: settings.key
Exception: (<class 'sqlite3.IntegrityError'>, IntegrityError('UNIQUE constraint failed: settings.key'), <traceback object at 0x00000245702BBA00>)
---
Traceback (most recent call last):
  File "C:\Users\nolan\personal\personal-projects\Nabu\data\database.py", line 43, in get_connection
    yield conn
  File "C:\Users\nolan\personal\personal-projects\Nabu\data\database.py", line 130, in insert
    cursor = conn.execute(query, tuple(data.values()))
sqlite3.IntegrityError: UNIQUE constraint failed: settings.key
2025-08-15 19:44:34,655 - data.database - ERROR - database:get_connection:47
Message: Database operation failed: UNIQUE constraint failed: settings.key
Exception: (<class 'sqlite3.IntegrityError'>, IntegrityError('UNIQUE constraint failed: settings.key'), <traceback object at 0x00000245702BBC80>)
---
Traceback (most recent call last):
  File "C:\Users\nolan\personal\personal-projects\Nabu\data\database.py", line 43, in get_connection
    yield conn
  File "C:\Users\nolan\personal\personal-projects\Nabu\data\database.py", line 130, in insert
    cursor = conn.execute(query, tuple(data.values()))
sqlite3.IntegrityError: UNIQUE constraint failed: settings.key
2025-08-15 19:44:34,679 - data.database - ERROR - database:get_connection:47
Message: Database operation failed: UNIQUE constraint failed: vocabulary.word, vocabulary.language
Exception: (<class 'sqlite3.IntegrityError'>, IntegrityError('UNIQUE constraint failed: vocabulary.word, vocabulary.language'), <traceback object at 0x00000245702BBA00>)
---
Traceback (most recent call last):
  File "C:\Users\nolan\personal\personal-projects\Nabu\data\database.py", line 43, in get_connection
    yield conn
  File "C:\Users\nolan\personal\personal-projects\Nabu\data\database.py", line 130, in insert
    cursor = conn.execute(query, tuple(data.values()))
sqlite3.IntegrityError: UNIQUE constraint failed: vocabulary.word, vocabulary.language
2025-08-15 19:44:34,685 - data.database - ERROR - database:get_connection:47
Message: Database operation failed: UNIQUE constraint failed: vocabulary.word, vocabulary.language
Exception: (<class 'sqlite3.IntegrityError'>, IntegrityError('UNIQUE constraint failed: vocabulary.word, vocabulary.language'), <traceback object at 0x00000245702BBC80>)
---
Traceback (most recent call last):
  File "C:\Users\nolan\personal\personal-projects\Nabu\data\database.py", line 43, in get_connection
    yield conn
  File "C:\Users\nolan\personal\personal-projects\Nabu\data\database.py", line 130, in insert
    cursor = conn.execute(query, tuple(data.values()))
sqlite3.IntegrityError: UNIQUE constraint failed: vocabulary.word, vocabulary.language
2025-08-15 19:53:15,018 - data.database - ERROR - database:get_connection:47
Message: Database operation failed: UNIQUE constraint failed: settings.key
Exception: (<class 'sqlite3.IntegrityError'>, IntegrityError('UNIQUE constraint failed: settings.key'), <traceback object at 0x0000020187CEDA00>)
---
Traceback (most recent call last):
  File "C:\Users\nolan\personal\personal-projects\Nabu\data\database.py", line 43, in get_connection
    yield conn
  File "C:\Users\nolan\personal\personal-projects\Nabu\data\database.py", line 130, in insert
    cursor = conn.execute(query, tuple(data.values()))
sqlite3.IntegrityError: UNIQUE constraint failed: settings.key
2025-08-15 19:53:15,025 - data.database - ERROR - database:get_connection:47
Message: Database operation failed: UNIQUE constraint failed: settings.key
Exception: (<class 'sqlite3.IntegrityError'>, IntegrityError('UNIQUE constraint failed: settings.key'), <traceback object at 0x0000020187CEDA00>)
---
Traceback (most recent call last):
  File "C:\Users\nolan\personal\personal-projects\Nabu\data\database.py", line 43, in get_connection
    yield conn
  File "C:\Users\nolan\personal\personal-projects\Nabu\data\database.py", line 130, in insert
    cursor = conn.execute(query, tuple(data.values()))
sqlite3.IntegrityError: UNIQUE constraint failed: settings.key
2025-08-15 19:53:15,030 - data.database - ERROR - database:get_connection:47
Message: Database operation failed: UNIQUE constraint failed: settings.key
Exception: (<class 'sqlite3.IntegrityError'>, IntegrityError('UNIQUE constraint failed: settings.key'), <traceback object at 0x0000020187CED300>)
---
Traceback (most recent call last):
  File "C:\Users\nolan\personal\personal-projects\Nabu\data\database.py", line 43, in get_connection
    yield conn
  File "C:\Users\nolan\personal\personal-projects\Nabu\data\database.py", line 130, in insert
    cursor = conn.execute(query, tuple(data.values()))
sqlite3.IntegrityError: UNIQUE constraint failed: settings.key
2025-08-15 19:53:15,040 - data.database - ERROR - database:get_connection:47
Message: Database operation failed: UNIQUE constraint failed: settings.key
Exception: (<class 'sqlite3.IntegrityError'>, IntegrityError('UNIQUE constraint failed: settings.key'), <traceback object at 0x00000201F5CDC080>)
---
Traceback (most recent call last):
  File "C:\Users\nolan\personal\personal-projects\Nabu\data\database.py", line 43, in get_connection
    yield conn
  File "C:\Users\nolan\personal\personal-projects\Nabu\data\database.py", line 130, in insert
    cursor = conn.execute(query, tuple(data.values()))
sqlite3.IntegrityError: UNIQUE constraint failed: settings.key
2025-08-15 19:53:15,049 - data.database - ERROR - database:get_connection:47
Message: Database operation failed: UNIQUE constraint failed: settings.key
Exception: (<class 'sqlite3.IntegrityError'>, IntegrityError('UNIQUE constraint failed: settings.key'), <traceback object at 0x00000201F5CDC080>)
---
Traceback (most recent call last):
  File "C:\Users\nolan\personal\personal-projects\Nabu\data\database.py", line 43, in get_connection
    yield conn
  File "C:\Users\nolan\personal\personal-projects\Nabu\data\database.py", line 130, in insert
    cursor = conn.execute(query, tuple(data.values()))
sqlite3.IntegrityError: UNIQUE constraint failed: settings.key
2025-08-15 19:53:15,056 - data.database - ERROR - database:get_connection:47
Message: Database operation failed: UNIQUE constraint failed: settings.key
Exception: (<class 'sqlite3.IntegrityError'>, IntegrityError('UNIQUE constraint failed: settings.key'), <traceback object at 0x0000020187CED400>)
---
Traceback (most recent call last):
  File "C:\Users\nolan\personal\personal-projects\Nabu\data\database.py", line 43, in get_connection
    yield conn
  File "C:\Users\nolan\personal\personal-projects\Nabu\data\database.py", line 130, in insert
    cursor = conn.execute(query, tuple(data.values()))
sqlite3.IntegrityError: UNIQUE constraint failed: settings.key
2025-08-15 19:53:15,060 - data.database - ERROR - database:get_connection:47
Message: Database operation failed: UNIQUE constraint failed: settings.key
Exception: (<class 'sqlite3.IntegrityError'>, IntegrityError('UNIQUE constraint failed: settings.key'), <traceback object at 0x0000020187CED400>)
---
Traceback (most recent call last):
  File "C:\Users\nolan\personal\personal-projects\Nabu\data\database.py", line 43, in get_connection
    yield conn
  File "C:\Users\nolan\personal\personal-projects\Nabu\data\database.py", line 130, in insert
    cursor = conn.execute(query, tuple(data.values()))
sqlite3.IntegrityError: UNIQUE constraint failed: settings.key
2025-08-15 19:53:15,071 - data.database - ERROR - database:get_connection:47
Message: Database operation failed: UNIQUE constraint failed: settings.key
Exception: (<class 'sqlite3.IntegrityError'>, IntegrityError('UNIQUE constraint failed: settings.key'), <traceback object at 0x0000020187B830C0>)
---
Traceback (most recent call last):
  File "C:\Users\nolan\personal\personal-projects\Nabu\data\database.py", line 43, in get_connection
    yield conn
  File "C:\Users\nolan\personal\personal-projects\Nabu\data\database.py", line 130, in insert
    cursor = conn.execute(query, tuple(data.values()))
sqlite3.IntegrityError: UNIQUE constraint failed: settings.key
2025-08-15 19:53:15,072 - data.database - ERROR - database:get_connection:47
Message: Database operation failed: UNIQUE constraint failed: settings.key
Exception: (<class 'sqlite3.IntegrityError'>, IntegrityError('UNIQUE constraint failed: settings.key'), <traceback object at 0x00000201F5CDC080>)
---
Traceback (most recent call last):
  File "C:\Users\nolan\personal\personal-projects\Nabu\data\database.py", line 43, in get_connection
    yield conn
  File "C:\Users\nolan\personal\personal-projects\Nabu\data\database.py", line 130, in insert
    cursor = conn.execute(query, tuple(data.values()))
sqlite3.IntegrityError: UNIQUE constraint failed: settings.key
2025-08-15 19:53:15,072 - data.database - ERROR - database:get_connection:47
Message: Database operation failed: UNIQUE constraint failed: settings.key
Exception: (<class 'sqlite3.IntegrityError'>, IntegrityError('UNIQUE constraint failed: settings.key'), <traceback object at 0x0000020187CED940>)
---
Traceback (most recent call last):
  File "C:\Users\nolan\personal\personal-projects\Nabu\data\database.py", line 43, in get_connection
    yield conn
  File "C:\Users\nolan\personal\personal-projects\Nabu\data\database.py", line 130, in insert
    cursor = conn.execute(query, tuple(data.values()))
sqlite3.IntegrityError: UNIQUE constraint failed: settings.key
2025-08-15 19:53:15,102 - data.database - ERROR - database:get_connection:47
Message: Database operation failed: UNIQUE constraint failed: vocabulary.word, vocabulary.language
Exception: (<class 'sqlite3.IntegrityError'>, IntegrityError('UNIQUE constraint failed: vocabulary.word, vocabulary.language'), <traceback object at 0x0000020187CEDAC0>)
---
Traceback (most recent call last):
  File "C:\Users\nolan\personal\personal-projects\Nabu\data\database.py", line 43, in get_connection
    yield conn
  File "C:\Users\nolan\personal\personal-projects\Nabu\data\database.py", line 130, in insert
    cursor = conn.execute(query, tuple(data.values()))
sqlite3.IntegrityError: UNIQUE constraint failed: vocabulary.word, vocabulary.language
2025-08-15 19:53:15,105 - data.database - ERROR - database:get_connection:47
Message: Database operation failed: UNIQUE constraint failed: vocabulary.word, vocabulary.language
Exception: (<class 'sqlite3.IntegrityError'>, IntegrityError('UNIQUE constraint failed: vocabulary.word, vocabulary.language'), <traceback object at 0x0000020187CEDAC0>)
---
Traceback (most recent call last):
  File "C:\Users\nolan\personal\personal-projects\Nabu\data\database.py", line 43, in get_connection
    yield conn
  File "C:\Users\nolan\personal\personal-projects\Nabu\data\database.py", line 130, in insert
    cursor = conn.execute(query, tuple(data.values()))
sqlite3.IntegrityError: UNIQUE constraint failed: vocabulary.word, vocabulary.language
2025-08-15 19:58:21,132 - data.database - ERROR - database:get_connection:47
Message: Database operation failed: UNIQUE constraint failed: settings.key
Exception: (<class 'sqlite3.IntegrityError'>, IntegrityError('UNIQUE constraint failed: settings.key'), <traceback object at 0x0000018ED95CBD40>)
---
Traceback (most recent call last):
  File "C:\Users\nolan\personal\personal-projects\Nabu\data\database.py", line 43, in get_connection
    yield conn
  File "C:\Users\nolan\personal\personal-projects\Nabu\data\database.py", line 130, in insert
    cursor = conn.execute(query, tuple(data.values()))
sqlite3.IntegrityError: UNIQUE constraint failed: settings.key
2025-08-15 19:58:21,139 - data.database - ERROR - database:get_connection:47
Message: Database operation failed: UNIQUE constraint failed: settings.key
Exception: (<class 'sqlite3.IntegrityError'>, IntegrityError('UNIQUE constraint failed: settings.key'), <traceback object at 0x0000018ED95CBDC0>)
---
Traceback (most recent call last):
  File "C:\Users\nolan\personal\personal-projects\Nabu\data\database.py", line 43, in get_connection
    yield conn
  File "C:\Users\nolan\personal\personal-projects\Nabu\data\database.py", line 130, in insert
    cursor = conn.execute(query, tuple(data.values()))
sqlite3.IntegrityError: UNIQUE constraint failed: settings.key
2025-08-15 19:58:21,143 - data.database - ERROR - database:get_connection:47
Message: Database operation failed: UNIQUE constraint failed: settings.key
Exception: (<class 'sqlite3.IntegrityError'>, IntegrityError('UNIQUE constraint failed: settings.key'), <traceback object at 0x0000018ED95CBD40>)
---
Traceback (most recent call last):
  File "C:\Users\nolan\personal\personal-projects\Nabu\data\database.py", line 43, in get_connection
    yield conn
  File "C:\Users\nolan\personal\personal-projects\Nabu\data\database.py", line 130, in insert
    cursor = conn.execute(query, tuple(data.values()))
sqlite3.IntegrityError: UNIQUE constraint failed: settings.key
2025-08-15 19:58:21,146 - data.database - ERROR - database:get_connection:47
Message: Database operation failed: UNIQUE constraint failed: settings.key
Exception: (<class 'sqlite3.IntegrityError'>, IntegrityError('UNIQUE constraint failed: settings.key'), <traceback object at 0x0000018ED95CBDC0>)
---
Traceback (most recent call last):
  File "C:\Users\nolan\personal\personal-projects\Nabu\data\database.py", line 43, in get_connection
    yield conn
  File "C:\Users\nolan\personal\personal-projects\Nabu\data\database.py", line 130, in insert
    cursor = conn.execute(query, tuple(data.values()))
sqlite3.IntegrityError: UNIQUE constraint failed: settings.key
2025-08-15 19:58:21,146 - data.database - ERROR - database:get_connection:47
Message: Database operation failed: UNIQUE constraint failed: settings.key
Exception: (<class 'sqlite3.IntegrityError'>, IntegrityError('UNIQUE constraint failed: settings.key'), <traceback object at 0x0000018ED95CBD40>)
---
Traceback (most recent call last):
  File "C:\Users\nolan\personal\personal-projects\Nabu\data\database.py", line 43, in get_connection
    yield conn
  File "C:\Users\nolan\personal\personal-projects\Nabu\data\database.py", line 130, in insert
    cursor = conn.execute(query, tuple(data.values()))
sqlite3.IntegrityError: UNIQUE constraint failed: settings.key
2025-08-15 19:58:21,152 - data.database - ERROR - database:get_connection:47
Message: Database operation failed: UNIQUE constraint failed: settings.key
Exception: (<class 'sqlite3.IntegrityError'>, IntegrityError('UNIQUE constraint failed: settings.key'), <traceback object at 0x0000018ED95CBDC0>)
---
Traceback (most recent call last):
  File "C:\Users\nolan\personal\personal-projects\Nabu\data\database.py", line 43, in get_connection
    yield conn
  File "C:\Users\nolan\personal\personal-projects\Nabu\data\database.py", line 130, in insert
    cursor = conn.execute(query, tuple(data.values()))
sqlite3.IntegrityError: UNIQUE constraint failed: settings.key
2025-08-15 19:58:21,156 - data.database - ERROR - database:get_connection:47
Message: Database operation failed: UNIQUE constraint failed: settings.key
Exception: (<class 'sqlite3.IntegrityError'>, IntegrityError('UNIQUE constraint failed: settings.key'), <traceback object at 0x0000018ED95CBD40>)
---
Traceback (most recent call last):
  File "C:\Users\nolan\personal\personal-projects\Nabu\data\database.py", line 43, in get_connection
    yield conn
  File "C:\Users\nolan\personal\personal-projects\Nabu\data\database.py", line 130, in insert
    cursor = conn.execute(query, tuple(data.values()))
sqlite3.IntegrityError: UNIQUE constraint failed: settings.key
2025-08-15 19:58:21,158 - data.database - ERROR - database:get_connection:47
Message: Database operation failed: UNIQUE constraint failed: settings.key
Exception: (<class 'sqlite3.IntegrityError'>, IntegrityError('UNIQUE constraint failed: settings.key'), <traceback object at 0x0000018ED95CBDC0>)
---
Traceback (most recent call last):
  File "C:\Users\nolan\personal\personal-projects\Nabu\data\database.py", line 43, in get_connection
    yield conn
  File "C:\Users\nolan\personal\personal-projects\Nabu\data\database.py", line 130, in insert
    cursor = conn.execute(query, tuple(data.values()))
sqlite3.IntegrityError: UNIQUE constraint failed: settings.key
2025-08-15 19:58:21,162 - data.database - ERROR - database:get_connection:47
Message: Database operation failed: UNIQUE constraint failed: settings.key
Exception: (<class 'sqlite3.IntegrityError'>, IntegrityError('UNIQUE constraint failed: settings.key'), <traceback object at 0x0000018ED95CBD40>)
---
Traceback (most recent call last):
  File "C:\Users\nolan\personal\personal-projects\Nabu\data\database.py", line 43, in get_connection
    yield conn
  File "C:\Users\nolan\personal\personal-projects\Nabu\data\database.py", line 130, in insert
    cursor = conn.execute(query, tuple(data.values()))
sqlite3.IntegrityError: UNIQUE constraint failed: settings.key
2025-08-15 19:58:21,162 - data.database - ERROR - database:get_connection:47
Message: Database operation failed: UNIQUE constraint failed: settings.key
Exception: (<class 'sqlite3.IntegrityError'>, IntegrityError('UNIQUE constraint failed: settings.key'), <traceback object at 0x0000018ED95CBDC0>)
---
Traceback (most recent call last):
  File "C:\Users\nolan\personal\personal-projects\Nabu\data\database.py", line 43, in get_connection
    yield conn
  File "C:\Users\nolan\personal\personal-projects\Nabu\data\database.py", line 130, in insert
    cursor = conn.execute(query, tuple(data.values()))
sqlite3.IntegrityError: UNIQUE constraint failed: settings.key
2025-08-15 19:58:21,178 - data.database - ERROR - database:get_connection:47
Message: Database operation failed: UNIQUE constraint failed: vocabulary.word, vocabulary.language
Exception: (<class 'sqlite3.IntegrityError'>, IntegrityError('UNIQUE constraint failed: vocabulary.word, vocabulary.language'), <traceback object at 0x0000018ED95CBD40>)
---
Traceback (most recent call last):
  File "C:\Users\nolan\personal\personal-projects\Nabu\data\database.py", line 43, in get_connection
    yield conn
  File "C:\Users\nolan\personal\personal-projects\Nabu\data\database.py", line 130, in insert
    cursor = conn.execute(query, tuple(data.values()))
sqlite3.IntegrityError: UNIQUE constraint failed: vocabulary.word, vocabulary.language
2025-08-15 19:58:21,178 - data.database - ERROR - database:get_connection:47
Message: Database operation failed: UNIQUE constraint failed: vocabulary.word, vocabulary.language
Exception: (<class 'sqlite3.IntegrityError'>, IntegrityError('UNIQUE constraint failed: vocabulary.word, vocabulary.language'), <traceback object at 0x0000018ED95CBDC0>)
---
Traceback (most recent call last):
  File "C:\Users\nolan\personal\personal-projects\Nabu\data\database.py", line 43, in get_connection
    yield conn
  File "C:\Users\nolan\personal\personal-projects\Nabu\data\database.py", line 130, in insert
    cursor = conn.execute(query, tuple(data.values()))
sqlite3.IntegrityError: UNIQUE constraint failed: vocabulary.word, vocabulary.language
2025-08-15 20:09:12,054 - data.database - ERROR - database:get_connection:47
Message: Database operation failed: UNIQUE constraint failed: settings.key
Exception: (<class 'sqlite3.IntegrityError'>, IntegrityError('UNIQUE constraint failed: settings.key'), <traceback object at 0x000001F6DD0DBC00>)
---
Traceback (most recent call last):
  File "C:\Users\nolan\personal\personal-projects\Nabu\data\database.py", line 43, in get_connection
    yield conn
  File "C:\Users\nolan\personal\personal-projects\Nabu\data\database.py", line 130, in insert
    cursor = conn.execute(query, tuple(data.values()))
sqlite3.IntegrityError: UNIQUE constraint failed: settings.key
2025-08-15 20:09:12,068 - data.database - ERROR - database:get_connection:47
Message: Database operation failed: UNIQUE constraint failed: settings.key
Exception: (<class 'sqlite3.IntegrityError'>, IntegrityError('UNIQUE constraint failed: settings.key'), <traceback object at 0x000001F6DD0DBFC0>)
---
Traceback (most recent call last):
  File "C:\Users\nolan\personal\personal-projects\Nabu\data\database.py", line 43, in get_connection
    yield conn
  File "C:\Users\nolan\personal\personal-projects\Nabu\data\database.py", line 130, in insert
    cursor = conn.execute(query, tuple(data.values()))
sqlite3.IntegrityError: UNIQUE constraint failed: settings.key
2025-08-15 20:09:12,068 - data.database - ERROR - database:get_connection:47
Message: Database operation failed: UNIQUE constraint failed: settings.key
Exception: (<class 'sqlite3.IntegrityError'>, IntegrityError('UNIQUE constraint failed: settings.key'), <traceback object at 0x000001F6DD0DBC00>)
---
Traceback (most recent call last):
  File "C:\Users\nolan\personal\personal-projects\Nabu\data\database.py", line 43, in get_connection
    yield conn
  File "C:\Users\nolan\personal\personal-projects\Nabu\data\database.py", line 130, in insert
    cursor = conn.execute(query, tuple(data.values()))
sqlite3.IntegrityError: UNIQUE constraint failed: settings.key
2025-08-15 20:09:12,082 - data.database - ERROR - database:get_connection:47
Message: Database operation failed: UNIQUE constraint failed: settings.key
Exception: (<class 'sqlite3.IntegrityError'>, IntegrityError('UNIQUE constraint failed: settings.key'), <traceback object at 0x000001F6DD0DBFC0>)
---
Traceback (most recent call last):
  File "C:\Users\nolan\personal\personal-projects\Nabu\data\database.py", line 43, in get_connection
    yield conn
  File "C:\Users\nolan\personal\personal-projects\Nabu\data\database.py", line 130, in insert
    cursor = conn.execute(query, tuple(data.values()))
sqlite3.IntegrityError: UNIQUE constraint failed: settings.key
2025-08-15 20:09:12,084 - data.database - ERROR - database:get_connection:47
Message: Database operation failed: UNIQUE constraint failed: settings.key
Exception: (<class 'sqlite3.IntegrityError'>, IntegrityError('UNIQUE constraint failed: settings.key'), <traceback object at 0x000001F6DD0DBC00>)
---
Traceback (most recent call last):
  File "C:\Users\nolan\personal\personal-projects\Nabu\data\database.py", line 43, in get_connection
    yield conn
  File "C:\Users\nolan\personal\personal-projects\Nabu\data\database.py", line 130, in insert
    cursor = conn.execute(query, tuple(data.values()))
sqlite3.IntegrityError: UNIQUE constraint failed: settings.key
2025-08-15 20:09:12,084 - data.database - ERROR - database:get_connection:47
Message: Database operation failed: UNIQUE constraint failed: settings.key
Exception: (<class 'sqlite3.IntegrityError'>, IntegrityError('UNIQUE constraint failed: settings.key'), <traceback object at 0x000001F6DD0DBFC0>)
---
Traceback (most recent call last):
  File "C:\Users\nolan\personal\personal-projects\Nabu\data\database.py", line 43, in get_connection
    yield conn
  File "C:\Users\nolan\personal\personal-projects\Nabu\data\database.py", line 130, in insert
    cursor = conn.execute(query, tuple(data.values()))
sqlite3.IntegrityError: UNIQUE constraint failed: settings.key
2025-08-15 20:09:12,096 - data.database - ERROR - database:get_connection:47
Message: Database operation failed: UNIQUE constraint failed: settings.key
Exception: (<class 'sqlite3.IntegrityError'>, IntegrityError('UNIQUE constraint failed: settings.key'), <traceback object at 0x000001F6DD0DBC00>)
---
Traceback (most recent call last):
  File "C:\Users\nolan\personal\personal-projects\Nabu\data\database.py", line 43, in get_connection
    yield conn
  File "C:\Users\nolan\personal\personal-projects\Nabu\data\database.py", line 130, in insert
    cursor = conn.execute(query, tuple(data.values()))
sqlite3.IntegrityError: UNIQUE constraint failed: settings.key
2025-08-15 20:09:12,100 - data.database - ERROR - database:get_connection:47
Message: Database operation failed: UNIQUE constraint failed: settings.key
Exception: (<class 'sqlite3.IntegrityError'>, IntegrityError('UNIQUE constraint failed: settings.key'), <traceback object at 0x000001F6DD0DBFC0>)
---
Traceback (most recent call last):
  File "C:\Users\nolan\personal\personal-projects\Nabu\data\database.py", line 43, in get_connection
    yield conn
  File "C:\Users\nolan\personal\personal-projects\Nabu\data\database.py", line 130, in insert
    cursor = conn.execute(query, tuple(data.values()))
sqlite3.IntegrityError: UNIQUE constraint failed: settings.key
2025-08-15 20:09:12,100 - data.database - ERROR - database:get_connection:47
Message: Database operation failed: UNIQUE constraint failed: settings.key
Exception: (<class 'sqlite3.IntegrityError'>, IntegrityError('UNIQUE constraint failed: settings.key'), <traceback object at 0x000001F6DD0DBC00>)
---
Traceback (most recent call last):
  File "C:\Users\nolan\personal\personal-projects\Nabu\data\database.py", line 43, in get_connection
    yield conn
  File "C:\Users\nolan\personal\personal-projects\Nabu\data\database.py", line 130, in insert
    cursor = conn.execute(query, tuple(data.values()))
sqlite3.IntegrityError: UNIQUE constraint failed: settings.key
2025-08-15 20:09:12,100 - data.database - ERROR - database:get_connection:47
Message: Database operation failed: UNIQUE constraint failed: settings.key
Exception: (<class 'sqlite3.IntegrityError'>, IntegrityError('UNIQUE constraint failed: settings.key'), <traceback object at 0x000001F6DD0DBFC0>)
---
Traceback (most recent call last):
  File "C:\Users\nolan\personal\personal-projects\Nabu\data\database.py", line 43, in get_connection
    yield conn
  File "C:\Users\nolan\personal\personal-projects\Nabu\data\database.py", line 130, in insert
    cursor = conn.execute(query, tuple(data.values()))
sqlite3.IntegrityError: UNIQUE constraint failed: settings.key
2025-08-15 20:09:12,114 - data.database - ERROR - database:get_connection:47
Message: Database operation failed: UNIQUE constraint failed: vocabulary.word, vocabulary.language
Exception: (<class 'sqlite3.IntegrityError'>, IntegrityError('UNIQUE constraint failed: vocabulary.word, vocabulary.language'), <traceback object at 0x000001F6DD0DBC00>)
---
Traceback (most recent call last):
  File "C:\Users\nolan\personal\personal-projects\Nabu\data\database.py", line 43, in get_connection
    yield conn
  File "C:\Users\nolan\personal\personal-projects\Nabu\data\database.py", line 130, in insert
    cursor = conn.execute(query, tuple(data.values()))
sqlite3.IntegrityError: UNIQUE constraint failed: vocabulary.word, vocabulary.language
2025-08-15 20:09:12,114 - data.database - ERROR - database:get_connection:47
Message: Database operation failed: UNIQUE constraint failed: vocabulary.word, vocabulary.language
Exception: (<class 'sqlite3.IntegrityError'>, IntegrityError('UNIQUE constraint failed: vocabulary.word, vocabulary.language'), <traceback object at 0x000001F6DD0DBFC0>)
---
Traceback (most recent call last):
  File "C:\Users\nolan\personal\personal-projects\Nabu\data\database.py", line 43, in get_connection
    yield conn
  File "C:\Users\nolan\personal\personal-projects\Nabu\data\database.py", line 130, in insert
    cursor = conn.execute(query, tuple(data.values()))
sqlite3.IntegrityError: UNIQUE constraint failed: vocabulary.word, vocabulary.language
2025-08-18 22:01:20,056 - __main__ - ERROR - main:initialize_application:45
Message: Application initialization failed: run_migrations() got an unexpected keyword argument 'create_sample_data'
Exception: (<class 'TypeError'>, TypeError("run_migrations() got an unexpected keyword argument 'create_sample_data'"), <traceback object at 0x0000029195BB1240>)
---
Traceback (most recent call last):
  File "C:\Users\nolan\personal\personal-projects\Nabu\main.py", line 39, in initialize_application
    run_migrations(db_manager, create_sample_data=True)
TypeError: run_migrations() got an unexpected keyword argument 'create_sample_data'
2025-08-18 22:04:34,023 - __main__ - ERROR - main:initialize_application:45
Message: Application initialization failed: run_migrations() got an unexpected keyword argument 'create_sample_data'
Exception: (<class 'TypeError'>, TypeError("run_migrations() got an unexpected keyword argument 'create_sample_data'"), <traceback object at 0x0000020350734380>)
---
Traceback (most recent call last):
  File "C:\Users\nolan\personal\personal-projects\Nabu\main.py", line 39, in initialize_application
    run_migrations(db_manager, create_sample_data=True)
TypeError: run_migrations() got an unexpected keyword argument 'create_sample_data'
2025-08-18 22:07:32,905 - __main__ - ERROR - main:initialize_application:45
Message: Application initialization failed: table user_profile has no column named username
Exception: (<class 'sqlite3.OperationalError'>, OperationalError('table user_profile has no column named username'), <traceback object at 0x0000020C151B58C0>)
---
Traceback (most recent call last):
  File "C:\Users\nolan\personal\personal-projects\Nabu\main.py", line 39, in initialize_application
    run_migrations(db_manager, create_sample_data=True)
  File "C:\Users\nolan\personal\personal-projects\Nabu\data\migrations.py", line 218, in run_migrations
    migration_manager.insert_sample_data()
  File "C:\Users\nolan\personal\personal-projects\Nabu\data\migrations.py", line 165, in insert_sample_data
    cursor.execute("""
sqlite3.OperationalError: table user_profile has no column named username
2025-08-18 22:08:26,735 - __main__ - ERROR - main:initialize_application:45
Message: Application initialization failed: table vocabulary has no column named user_id
Exception: (<class 'sqlite3.OperationalError'>, OperationalError('table vocabulary has no column named user_id'), <traceback object at 0x000001D80D29EC00>)
---
Traceback (most recent call last):
  File "C:\Users\nolan\personal\personal-projects\Nabu\main.py", line 39, in initialize_application
    run_migrations(db_manager, create_sample_data=True)
  File "C:\Users\nolan\personal\personal-projects\Nabu\data\migrations.py", line 247, in run_migrations
    migration_manager.insert_sample_data()
  File "C:\Users\nolan\personal\personal-projects\Nabu\data\migrations.py", line 210, in insert_sample_data
    cursor.execute("""
sqlite3.OperationalError: table vocabulary has no column named user_id
2025-08-18 22:09:23,853 - __main__ - ERROR - main:initialize_application:45
Message: Application initialization failed: table learning_sessions has no column named user_id
Exception: (<class 'sqlite3.OperationalError'>, OperationalError('table learning_sessions has no column named user_id'), <traceback object at 0x000002D889E27500>)
---
Traceback (most recent call last):
  File "C:\Users\nolan\personal\personal-projects\Nabu\main.py", line 39, in initialize_application
    run_migrations(db_manager, create_sample_data=True)
  File "C:\Users\nolan\personal\personal-projects\Nabu\data\migrations.py", line 275, in run_migrations
    migration_manager.insert_sample_data()
  File "C:\Users\nolan\personal\personal-projects\Nabu\data\migrations.py", line 244, in insert_sample_data
    cursor.execute("""
sqlite3.OperationalError: table learning_sessions has no column named user_id
2025-08-18 22:13:49,828 - data.database - ERROR - database:get_connection:47
Message: Database operation failed: Error binding parameter 2 - probably unsupported type.
Exception: (<class 'sqlite3.InterfaceError'>, InterfaceError('Error binding parameter 2 - probably unsupported type.'), <traceback object at 0x000001D0335DE700>)
---
Traceback (most recent call last):
  File "C:\Users\nolan\personal\personal-projects\Nabu\data\database.py", line 43, in get_connection
    yield conn
  File "C:\Users\nolan\personal\personal-projects\Nabu\data\database.py", line 140, in update
    cursor = conn.execute(query, tuple(data.values()) + where_params)
sqlite3.InterfaceError: Error binding parameter 2 - probably unsupported type.
2025-08-18 22:13:49,832 - core.session_manager - ERROR - session_manager:_update_session_in_db:330
Message: Failed to update session in database: Error binding parameter 2 - probably unsupported type.
Exception: (<class 'sqlite3.InterfaceError'>, InterfaceError('Error binding parameter 2 - probably unsupported type.'), <traceback object at 0x000001D02EE815C0>)
---
Traceback (most recent call last):
  File "C:\Users\nolan\personal\personal-projects\Nabu\core\session_manager.py", line 327, in _update_session_in_db
    self.db.update('learning_sessions', data, 'id = ?', (session.session_id,))
  File "C:\Users\nolan\personal\personal-projects\Nabu\data\database.py", line 140, in update
    cursor = conn.execute(query, tuple(data.values()) + where_params)
sqlite3.InterfaceError: Error binding parameter 2 - probably unsupported type.
2025-08-18 22:13:49,853 - ui.conversation - ERROR - conversation:_end_session:198
Message: Failed to end session: maximum recursion depth exceeded while calling a Python object
Exception: None
---

2025-08-18 22:27:51,981 - data.database - ERROR - database:get_connection:47
Message: Database operation failed: Error binding parameter 2 - probably unsupported type.
Exception: (<class 'sqlite3.InterfaceError'>, InterfaceError('Error binding parameter 2 - probably unsupported type.'), <traceback object at 0x000001CF088822C0>)
---
Traceback (most recent call last):
  File "C:\Users\nolan\personal\personal-projects\Nabu\data\database.py", line 43, in get_connection
    yield conn
  File "C:\Users\nolan\personal\personal-projects\Nabu\data\database.py", line 140, in update
    cursor = conn.execute(query, tuple(data.values()) + where_params)
sqlite3.InterfaceError: Error binding parameter 2 - probably unsupported type.
2025-08-18 22:27:51,985 - core.session_manager - ERROR - session_manager:_update_session_in_db:330
Message: Failed to update session in database: Error binding parameter 2 - probably unsupported type.
Exception: (<class 'sqlite3.InterfaceError'>, InterfaceError('Error binding parameter 2 - probably unsupported type.'), <traceback object at 0x000001CF0886C940>)
---
Traceback (most recent call last):
  File "C:\Users\nolan\personal\personal-projects\Nabu\core\session_manager.py", line 327, in _update_session_in_db
    self.db.update('learning_sessions', data, 'id = ?', (session.session_id,))
  File "C:\Users\nolan\personal\personal-projects\Nabu\data\database.py", line 140, in update
    cursor = conn.execute(query, tuple(data.values()) + where_params)
sqlite3.InterfaceError: Error binding parameter 2 - probably unsupported type.
2025-08-18 22:27:52,010 - ui.conversation - ERROR - conversation:_end_session:198
Message: Failed to end session: maximum recursion depth exceeded while calling a Python object
Exception: None
---

2025-08-18 22:32:36,420 - data.database - ERROR - database:get_connection:47
Message: Database operation failed: Error binding parameter 2 - probably unsupported type.
Exception: (<class 'sqlite3.InterfaceError'>, InterfaceError('Error binding parameter 2 - probably unsupported type.'), <traceback object at 0x000001D3D9889A00>)
---
Traceback (most recent call last):
  File "C:\Users\nolan\personal\personal-projects\Nabu\data\database.py", line 43, in get_connection
    yield conn
  File "C:\Users\nolan\personal\personal-projects\Nabu\data\database.py", line 140, in update
    cursor = conn.execute(query, tuple(data.values()) + where_params)
sqlite3.InterfaceError: Error binding parameter 2 - probably unsupported type.
2025-08-18 22:32:36,424 - core.session_manager - ERROR - session_manager:_update_session_in_db:331
Message: Failed to update session in database: Error binding parameter 2 - probably unsupported type.
Exception: (<class 'sqlite3.InterfaceError'>, InterfaceError('Error binding parameter 2 - probably unsupported type.'), <traceback object at 0x000001D3D9754A40>)
---
Traceback (most recent call last):
  File "C:\Users\nolan\personal\personal-projects\Nabu\core\session_manager.py", line 328, in _update_session_in_db
    self.db.update('learning_sessions', data, 'id = ?', (session.session_id,))
  File "C:\Users\nolan\personal\personal-projects\Nabu\data\database.py", line 140, in update
    cursor = conn.execute(query, tuple(data.values()) + where_params)
sqlite3.InterfaceError: Error binding parameter 2 - probably unsupported type.
2025-08-18 22:32:36,450 - ui.conversation - ERROR - conversation:_end_session:198
Message: Failed to end session: maximum recursion depth exceeded while calling a Python object
Exception: None
---

2025-08-18 22:41:53,350 - data.database - ERROR - database:get_connection:47
Message: Database operation failed: Error binding parameter 2 - probably unsupported type.
Exception: (<class 'sqlite3.InterfaceError'>, InterfaceError('Error binding parameter 2 - probably unsupported type.'), <traceback object at 0x00000279B079E6C0>)
---
Traceback (most recent call last):
  File "C:\Users\nolan\personal\personal-projects\Nabu\data\database.py", line 43, in get_connection
    yield conn
  File "C:\Users\nolan\personal\personal-projects\Nabu\data\database.py", line 140, in update
    cursor = conn.execute(query, tuple(data.values()) + where_params)
sqlite3.InterfaceError: Error binding parameter 2 - probably unsupported type.
2025-08-18 22:41:53,358 - core.session_manager - ERROR - session_manager:_update_session_in_db:331
Message: Failed to update session in database: Error binding parameter 2 - probably unsupported type.
Exception: (<class 'sqlite3.InterfaceError'>, InterfaceError('Error binding parameter 2 - probably unsupported type.'), <traceback object at 0x00000279ABF81040>)
---
Traceback (most recent call last):
  File "C:\Users\nolan\personal\personal-projects\Nabu\core\session_manager.py", line 328, in _update_session_in_db
    self.db.update('learning_sessions', data, 'id = ?', (session.session_id,))
  File "C:\Users\nolan\personal\personal-projects\Nabu\data\database.py", line 140, in update
    cursor = conn.execute(query, tuple(data.values()) + where_params)
sqlite3.InterfaceError: Error binding parameter 2 - probably unsupported type.
2025-08-18 22:41:53,400 - ui.conversation - ERROR - conversation:_end_session:198
Message: Failed to end session: maximum recursion depth exceeded while calling a Python object
Exception: None
---

2025-08-18 22:48:25,913 - ui.conversation - ERROR - conversation:_end_session:198
Message: Failed to end session: maximum recursion depth exceeded while calling a Python object
Exception: None
---

2025-08-23 17:45:14,831 - core.event_bus - ERROR - event_bus:publish:69
Message: Error in event callback for user_message: main thread is not in main loop
Exception: (<class 'RuntimeError'>, RuntimeError('main thread is not in main loop'), <traceback object at 0x000002B271B0C340>)
---
Traceback (most recent call last):
  File "C:\Users\nolan\personal\personal-projects\Nabu\core\event_bus.py", line 67, in publish
    callback(data)
  File "C:\Users\nolan\personal\personal-projects\Nabu\ui\conversation.py", line 263, in _on_user_message
    self._add_message("User", text, "user")
  File "C:\Users\nolan\personal\personal-projects\Nabu\ui\conversation.py", line 224, in _add_message
    self.conversation_text.insert(tk.END, formatted_message)
  File "C:\Users\nolan\Anaconda3\lib\tkinter\__init__.py", line 3743, in insert
    self.tk.call((self._w, 'insert', index, chars) + args)
RuntimeError: main thread is not in main loop
2025-08-23 17:46:15,490 - core.event_bus - ERROR - event_bus:publish:69
Message: Error in event callback for user_message: main thread is not in main loop
Exception: (<class 'RuntimeError'>, RuntimeError('main thread is not in main loop'), <traceback object at 0x000001EEF8ADEC40>)
---
Traceback (most recent call last):
  File "C:\Users\nolan\personal\personal-projects\Nabu\core\event_bus.py", line 67, in publish
    callback(data)
  File "C:\Users\nolan\personal\personal-projects\Nabu\ui\conversation.py", line 263, in _on_user_message
    self._add_message("User", text, "user")
  File "C:\Users\nolan\personal\personal-projects\Nabu\ui\conversation.py", line 224, in _add_message
    self.conversation_text.insert(tk.END, formatted_message)
  File "C:\Users\nolan\Anaconda3\lib\tkinter\__init__.py", line 3743, in insert
    self.tk.call((self._w, 'insert', index, chars) + args)
RuntimeError: main thread is not in main loop
2025-08-23 17:46:17,030 - core.event_bus - ERROR - event_bus:publish:69
Message: Error in event callback for ai_response: main thread is not in main loop
Exception: (<class 'RuntimeError'>, RuntimeError('main thread is not in main loop'), <traceback object at 0x000001EEF8ADC840>)
---
Traceback (most recent call last):
  File "C:\Users\nolan\personal\personal-projects\Nabu\core\event_bus.py", line 67, in publish
    callback(data)
  File "C:\Users\nolan\personal\personal-projects\Nabu\ui\conversation.py", line 270, in _on_ai_response
    self._add_message("AI", text, "ai")
  File "C:\Users\nolan\personal\personal-projects\Nabu\ui\conversation.py", line 224, in _add_message
    self.conversation_text.insert(tk.END, formatted_message)
  File "C:\Users\nolan\Anaconda3\lib\tkinter\__init__.py", line 3743, in insert
    self.tk.call((self._w, 'insert', index, chars) + args)
RuntimeError: main thread is not in main loop
2025-08-23 18:31:08,577 - ui.vocab_tab - ERROR - vocab_tab:_load_vocabulary:224
Message: Error loading vocabulary: 'DatabaseManager' object has no attribute 'execute_query'
Exception: None
---

2025-08-23 18:31:08,601 - ui.media_tab - ERROR - media_tab:_load_media:231
Message: Error loading media: 'DatabaseManager' object has no attribute 'execute_query'
Exception: None
---

2025-08-23 18:31:08,609 - ui.grammar_tab - ERROR - grammar_tab:_load_grammar_topics:225
Message: Error loading grammar topics: 'DatabaseManager' object has no attribute 'execute_query'
Exception: None
---

2025-08-23 18:31:08,618 - ui.notes_tab - ERROR - notes_tab:_load_notes:224
Message: Error loading notes: 'DatabaseManager' object has no attribute 'execute_query'
Exception: None
---

2025-08-23 18:31:08,675 - __main__ - ERROR - main:main:68
Message: Application crashed: name 'config' is not defined
Exception: (<class 'NameError'>, NameError("name 'config' is not defined"), <traceback object at 0x000002B5B27D6780>)
---
Traceback (most recent call last):
  File "C:\Users\nolan\personal\personal-projects\Nabu\main.py", line 59, in main
    app = TutorApplication()
  File "C:\Users\nolan\personal\personal-projects\Nabu\core\application.py", line 45, in __init__
    self._initialize_ui()
  File "C:\Users\nolan\personal\personal-projects\Nabu\core\application.py", line 92, in _initialize_ui
    self.conversation_frame = ConversationFrame(
  File "C:\Users\nolan\personal\personal-projects\Nabu\ui\conversation.py", line 37, in __init__
    self._setup_ui()
  File "C:\Users\nolan\personal\personal-projects\Nabu\ui\conversation.py", line 121, in _setup_ui
    self.test_mode_var = tk.BooleanVar(value=config.learning.test_mode)
NameError: name 'config' is not defined
2025-08-23 18:31:34,843 - ui.vocab_tab - ERROR - vocab_tab:_load_vocabulary:224
Message: Error loading vocabulary: 'DatabaseManager' object has no attribute 'execute_query'
Exception: None
---

2025-08-23 18:31:34,879 - ui.media_tab - ERROR - media_tab:_load_media:231
Message: Error loading media: 'DatabaseManager' object has no attribute 'execute_query'
Exception: None
---

2025-08-23 18:31:34,888 - ui.grammar_tab - ERROR - grammar_tab:_load_grammar_topics:225
Message: Error loading grammar topics: 'DatabaseManager' object has no attribute 'execute_query'
Exception: None
---

2025-08-23 18:31:34,900 - ui.notes_tab - ERROR - notes_tab:_load_notes:224
Message: Error loading notes: 'DatabaseManager' object has no attribute 'execute_query'
Exception: None
---

2025-08-23 18:31:34,976 - __main__ - ERROR - main:main:68
Message: Application crashed: name 'config' is not defined
Exception: (<class 'NameError'>, NameError("name 'config' is not defined"), <traceback object at 0x000001AB095245C0>)
---
Traceback (most recent call last):
  File "C:\Users\nolan\personal\personal-projects\Nabu\main.py", line 59, in main
    app = TutorApplication()
  File "C:\Users\nolan\personal\personal-projects\Nabu\core\application.py", line 45, in __init__
    self._initialize_ui()
  File "C:\Users\nolan\personal\personal-projects\Nabu\core\application.py", line 92, in _initialize_ui
    self.conversation_frame = ConversationFrame(
  File "C:\Users\nolan\personal\personal-projects\Nabu\ui\conversation.py", line 37, in __init__
    self._setup_ui()
  File "C:\Users\nolan\personal\personal-projects\Nabu\ui\conversation.py", line 121, in _setup_ui
    self.test_mode_var = tk.BooleanVar(value=config.learning.test_mode)
NameError: name 'config' is not defined
2025-08-23 18:35:39,394 - ui.vocab_tab - ERROR - vocab_tab:_load_vocabulary:224
Message: Error loading vocabulary: Cannot operate on a closed database.
Exception: None
---

2025-08-23 18:35:39,425 - ui.media_tab - ERROR - media_tab:_load_media:231
Message: Error loading media: Cannot operate on a closed database.
Exception: None
---

2025-08-23 18:35:39,436 - ui.grammar_tab - ERROR - grammar_tab:_load_grammar_topics:225
Message: Error loading grammar topics: Cannot operate on a closed database.
Exception: None
---

2025-08-23 18:35:39,447 - data.database - ERROR - database:get_connection:66
Message: Database operation failed: no such column: title
Exception: (<class 'sqlite3.OperationalError'>, OperationalError('no such column: title'), <traceback object at 0x00000197AA9CF480>)
---
Traceback (most recent call last):
  File "C:\Users\nolan\personal\personal-projects\Nabu\data\database.py", line 62, in get_connection
    yield conn
  File "C:\Users\nolan\personal\personal-projects\Nabu\data\database.py", line 104, in execute
    cursor = conn.execute(query, params)
sqlite3.OperationalError: no such column: title
2025-08-23 18:35:39,450 - ui.notes_tab - ERROR - notes_tab:_load_notes:224
Message: Error loading notes: no such column: title
Exception: None
---

2025-08-23 18:35:44,686 - ui.vocab_tab - ERROR - vocab_tab:_load_vocabulary:224
Message: Error loading vocabulary: Cannot operate on a closed database.
Exception: None
---

2025-08-23 18:35:45,722 - ui.media_tab - ERROR - media_tab:_load_media:231
Message: Error loading media: Cannot operate on a closed database.
Exception: None
---

2025-08-23 18:35:46,928 - ui.grammar_tab - ERROR - grammar_tab:_load_grammar_topics:225
Message: Error loading grammar topics: Cannot operate on a closed database.
Exception: None
---

2025-08-23 18:35:47,923 - data.database - ERROR - database:get_connection:66
Message: Database operation failed: no such column: title
Exception: (<class 'sqlite3.OperationalError'>, OperationalError('no such column: title'), <traceback object at 0x00000197AA9E1740>)
---
Traceback (most recent call last):
  File "C:\Users\nolan\personal\personal-projects\Nabu\data\database.py", line 62, in get_connection
    yield conn
  File "C:\Users\nolan\personal\personal-projects\Nabu\data\database.py", line 104, in execute
    cursor = conn.execute(query, params)
sqlite3.OperationalError: no such column: title
2025-08-23 18:35:47,925 - ui.notes_tab - ERROR - notes_tab:_load_notes:224
Message: Error loading notes: no such column: title
Exception: None
---

2025-08-23 18:35:53,404 - ui.grammar_tab - ERROR - grammar_tab:_load_grammar_topics:225
Message: Error loading grammar topics: Cannot operate on a closed database.
Exception: None
---

2025-08-23 18:35:53,911 - data.database - ERROR - database:get_connection:66
Message: Database operation failed: no such column: title
Exception: (<class 'sqlite3.OperationalError'>, OperationalError('no such column: title'), <traceback object at 0x00000197AAAA2880>)
---
Traceback (most recent call last):
  File "C:\Users\nolan\personal\personal-projects\Nabu\data\database.py", line 62, in get_connection
    yield conn
  File "C:\Users\nolan\personal\personal-projects\Nabu\data\database.py", line 104, in execute
    cursor = conn.execute(query, params)
sqlite3.OperationalError: no such column: title
2025-08-23 18:35:53,914 - ui.notes_tab - ERROR - notes_tab:_load_notes:224
Message: Error loading notes: no such column: title
Exception: None
---

2025-08-23 18:35:54,588 - ui.grammar_tab - ERROR - grammar_tab:_load_grammar_topics:225
Message: Error loading grammar topics: Cannot operate on a closed database.
Exception: None
---

2025-08-23 18:35:55,071 - ui.media_tab - ERROR - media_tab:_load_media:231
Message: Error loading media: Cannot operate on a closed database.
Exception: None
---

2025-08-23 18:35:55,550 - ui.vocab_tab - ERROR - vocab_tab:_load_vocabulary:224
Message: Error loading vocabulary: Cannot operate on a closed database.
Exception: None
---

2025-08-23 18:42:31,489 - ui.vocab_tab - ERROR - vocab_tab:_load_vocabulary:228
Message: Error loading vocabulary: Cannot operate on a closed database.
Exception: None
---

2025-08-23 18:42:31,510 - ui.media_tab - ERROR - media_tab:_load_media:235
Message: Error loading media: Cannot operate on a closed database.
Exception: None
---

2025-08-23 18:42:31,534 - ui.grammar_tab - ERROR - grammar_tab:_load_grammar_topics:229
Message: Error loading grammar topics: Cannot operate on a closed database.
Exception: None
---

2025-08-23 18:42:31,568 - data.database - ERROR - database:get_connection:66
Message: Database operation failed: no such column: title
Exception: (<class 'sqlite3.OperationalError'>, OperationalError('no such column: title'), <traceback object at 0x000001408D16F140>)
---
Traceback (most recent call last):
  File "C:\Users\nolan\personal\personal-projects\Nabu\data\database.py", line 62, in get_connection
    yield conn
  File "C:\Users\nolan\personal\personal-projects\Nabu\data\database.py", line 104, in execute
    cursor = conn.execute(query, params)
sqlite3.OperationalError: no such column: title
2025-08-23 18:42:31,570 - ui.notes_tab - ERROR - notes_tab:_load_notes:226
Message: Error loading notes: no such column: title
Exception: None
---

2025-08-23 18:42:35,560 - ui.vocab_tab - ERROR - vocab_tab:_load_vocabulary:228
Message: Error loading vocabulary: Cannot operate on a closed database.
Exception: None
---

2025-08-23 18:42:36,049 - ui.media_tab - ERROR - media_tab:_load_media:235
Message: Error loading media: Cannot operate on a closed database.
Exception: None
---

2025-08-23 18:42:36,489 - ui.grammar_tab - ERROR - grammar_tab:_load_grammar_topics:229
Message: Error loading grammar topics: Cannot operate on a closed database.
Exception: None
---

2025-08-23 18:42:36,900 - data.database - ERROR - database:get_connection:66
Message: Database operation failed: no such column: title
Exception: (<class 'sqlite3.OperationalError'>, OperationalError('no such column: title'), <traceback object at 0x000001408D186480>)
---
Traceback (most recent call last):
  File "C:\Users\nolan\personal\personal-projects\Nabu\data\database.py", line 62, in get_connection
    yield conn
  File "C:\Users\nolan\personal\personal-projects\Nabu\data\database.py", line 104, in execute
    cursor = conn.execute(query, params)
sqlite3.OperationalError: no such column: title
2025-08-23 18:42:36,904 - ui.notes_tab - ERROR - notes_tab:_load_notes:226
Message: Error loading notes: no such column: title
Exception: None
---

2025-08-23 18:43:47,236 - data.database - ERROR - database:get_connection:66
Message: Database operation failed: no such column: title
Exception: (<class 'sqlite3.OperationalError'>, OperationalError('no such column: title'), <traceback object at 0x000002D5D8662440>)
---
Traceback (most recent call last):
  File "C:\Users\nolan\personal\personal-projects\Nabu\data\database.py", line 62, in get_connection
    yield conn
  File "C:\Users\nolan\personal\personal-projects\Nabu\data\database.py", line 104, in execute
    cursor = conn.execute(query, params)
sqlite3.OperationalError: no such column: title
2025-08-23 18:43:47,239 - ui.notes_tab - ERROR - notes_tab:_load_notes:226
Message: Error loading notes: no such column: title
Exception: None
---

2025-08-23 18:52:03,181 - data.database - ERROR - database:get_connection:66
Message: Database operation failed: no such column: v.mastery_score
Exception: (<class 'sqlite3.OperationalError'>, OperationalError('no such column: v.mastery_score'), <traceback object at 0x0000023DC6C3B3C0>)
---
Traceback (most recent call last):
  File "C:\Users\nolan\personal\personal-projects\Nabu\data\database.py", line 62, in get_connection
    yield conn
  File "C:\Users\nolan\personal\personal-projects\Nabu\data\database.py", line 104, in execute
    cursor = conn.execute(query, params)
sqlite3.OperationalError: no such column: v.mastery_score
2025-08-23 18:52:03,183 - ui.vocab_tab - ERROR - vocab_tab:_load_vocabulary:243
Message: Error loading vocabulary: no such column: v.mastery_score
Exception: None
---

2025-08-23 19:28:25,955 - data.database - ERROR - database:get_connection:66
Message: Database operation failed: table learning_sessions has no column named started_at
Exception: (<class 'sqlite3.OperationalError'>, OperationalError('table learning_sessions has no column named started_at'), <traceback object at 0x000001E0418C7D40>)
---
Traceback (most recent call last):
  File "C:\Users\nolan\personal\personal-projects\Nabu\data\database.py", line 62, in get_connection
    yield conn
  File "C:\Users\nolan\personal\personal-projects\Nabu\data\database.py", line 154, in insert
    cursor = conn.execute(query, tuple(sanitized_data.values()))
sqlite3.OperationalError: table learning_sessions has no column named started_at
2025-08-23 19:28:25,965 - core.session_manager - ERROR - session_manager:_save_session_to_db:312
Message: Failed to save session to database: table learning_sessions has no column named started_at
Exception: (<class 'sqlite3.OperationalError'>, OperationalError('table learning_sessions has no column named started_at'), <traceback object at 0x000001E0415AA100>)
---
Traceback (most recent call last):
  File "C:\Users\nolan\personal\personal-projects\Nabu\core\session_manager.py", line 309, in _save_session_to_db
    self.db.insert('learning_sessions', data)
  File "C:\Users\nolan\personal\personal-projects\Nabu\data\database.py", line 154, in insert
    cursor = conn.execute(query, tuple(sanitized_data.values()))
sqlite3.OperationalError: table learning_sessions has no column named started_at
2025-08-23 19:28:50,690 - data.database - ERROR - database:get_connection:66
Message: Database operation failed: no such column: ended_at
Exception: (<class 'sqlite3.OperationalError'>, OperationalError('no such column: ended_at'), <traceback object at 0x000001E045E11100>)
---
Traceback (most recent call last):
  File "C:\Users\nolan\personal\personal-projects\Nabu\data\database.py", line 62, in get_connection
    yield conn
  File "C:\Users\nolan\personal\personal-projects\Nabu\data\database.py", line 165, in update
    cursor = conn.execute(query, tuple(sanitized_data.values()) + where_params)
sqlite3.OperationalError: no such column: ended_at
2025-08-23 19:28:50,693 - core.session_manager - ERROR - session_manager:_update_session_in_db:331
Message: Failed to update session in database: no such column: ended_at
Exception: (<class 'sqlite3.OperationalError'>, OperationalError('no such column: ended_at'), <traceback object at 0x000001E045E18D00>)
---
Traceback (most recent call last):
  File "C:\Users\nolan\personal\personal-projects\Nabu\core\session_manager.py", line 328, in _update_session_in_db
    self.db.update('learning_sessions', data, 'id = ?', (session.session_id,))
  File "C:\Users\nolan\personal\personal-projects\Nabu\data\database.py", line 165, in update
    cursor = conn.execute(query, tuple(sanitized_data.values()) + where_params)
sqlite3.OperationalError: no such column: ended_at
2025-08-23 19:28:54,485 - data.database - ERROR - database:get_connection:66
Message: Database operation failed: no such column: ended_at
Exception: (<class 'sqlite3.OperationalError'>, OperationalError('no such column: ended_at'), <traceback object at 0x000001E045DE5EC0>)
---
Traceback (most recent call last):
  File "C:\Users\nolan\personal\personal-projects\Nabu\data\database.py", line 62, in get_connection
    yield conn
  File "C:\Users\nolan\personal\personal-projects\Nabu\data\database.py", line 165, in update
    cursor = conn.execute(query, tuple(sanitized_data.values()) + where_params)
sqlite3.OperationalError: no such column: ended_at
2025-08-23 19:28:54,490 - core.session_manager - ERROR - session_manager:_update_session_in_db:331
Message: Failed to update session in database: no such column: ended_at
Exception: (<class 'sqlite3.OperationalError'>, OperationalError('no such column: ended_at'), <traceback object at 0x000001E045DDD6C0>)
---
Traceback (most recent call last):
  File "C:\Users\nolan\personal\personal-projects\Nabu\core\session_manager.py", line 328, in _update_session_in_db
    self.db.update('learning_sessions', data, 'id = ?', (session.session_id,))
  File "C:\Users\nolan\personal\personal-projects\Nabu\data\database.py", line 165, in update
    cursor = conn.execute(query, tuple(sanitized_data.values()) + where_params)
sqlite3.OperationalError: no such column: ended_at
2025-08-23 19:30:07,306 - data.database - ERROR - database:get_connection:66
Message: Database operation failed: table learning_sessions has no column named mode
Exception: (<class 'sqlite3.OperationalError'>, OperationalError('table learning_sessions has no column named mode'), <traceback object at 0x0000023800177D80>)
---
Traceback (most recent call last):
  File "C:\Users\nolan\personal\personal-projects\Nabu\data\database.py", line 62, in get_connection
    yield conn
  File "C:\Users\nolan\personal\personal-projects\Nabu\data\database.py", line 154, in insert
    cursor = conn.execute(query, tuple(sanitized_data.values()))
sqlite3.OperationalError: table learning_sessions has no column named mode
2025-08-23 19:30:07,312 - core.session_manager - ERROR - session_manager:_save_session_to_db:312
Message: Failed to save session to database: table learning_sessions has no column named mode
Exception: (<class 'sqlite3.OperationalError'>, OperationalError('table learning_sessions has no column named mode'), <traceback object at 0x000002387FE5A240>)
---
Traceback (most recent call last):
  File "C:\Users\nolan\personal\personal-projects\Nabu\core\session_manager.py", line 309, in _save_session_to_db
    self.db.insert('learning_sessions', data)
  File "C:\Users\nolan\personal\personal-projects\Nabu\data\database.py", line 154, in insert
    cursor = conn.execute(query, tuple(sanitized_data.values()))
sqlite3.OperationalError: table learning_sessions has no column named mode
2025-08-23 19:30:26,628 - data.database - ERROR - database:get_connection:66
Message: Database operation failed: no such column: summary
Exception: (<class 'sqlite3.OperationalError'>, OperationalError('no such column: summary'), <traceback object at 0x000002380464E6C0>)
---
Traceback (most recent call last):
  File "C:\Users\nolan\personal\personal-projects\Nabu\data\database.py", line 62, in get_connection
    yield conn
  File "C:\Users\nolan\personal\personal-projects\Nabu\data\database.py", line 165, in update
    cursor = conn.execute(query, tuple(sanitized_data.values()) + where_params)
sqlite3.OperationalError: no such column: summary
2025-08-23 19:30:26,635 - core.session_manager - ERROR - session_manager:_update_session_in_db:331
Message: Failed to update session in database: no such column: summary
Exception: (<class 'sqlite3.OperationalError'>, OperationalError('no such column: summary'), <traceback object at 0x0000023804614E00>)
---
Traceback (most recent call last):
  File "C:\Users\nolan\personal\personal-projects\Nabu\core\session_manager.py", line 328, in _update_session_in_db
    self.db.update('learning_sessions', data, 'id = ?', (session.session_id,))
  File "C:\Users\nolan\personal\personal-projects\Nabu\data\database.py", line 165, in update
    cursor = conn.execute(query, tuple(sanitized_data.values()) + where_params)
sqlite3.OperationalError: no such column: summary
2025-08-23 19:51:39,238 - data.database - ERROR - database:get_connection:66
Message: Database operation failed: table learning_sessions has no column named vocab_practiced
Exception: (<class 'sqlite3.OperationalError'>, OperationalError('table learning_sessions has no column named vocab_practiced'), <traceback object at 0x0000028DC52C8600>)
---
Traceback (most recent call last):
  File "C:\Users\nolan\personal\personal-projects\Nabu\data\database.py", line 62, in get_connection
    yield conn
  File "C:\Users\nolan\personal\personal-projects\Nabu\data\database.py", line 154, in insert
    cursor = conn.execute(query, tuple(sanitized_data.values()))
sqlite3.OperationalError: table learning_sessions has no column named vocab_practiced
2025-08-23 19:51:39,242 - core.session_manager - ERROR - session_manager:_save_session_to_db:335
Message: Failed to save session to database: table learning_sessions has no column named vocab_practiced
Exception: (<class 'sqlite3.OperationalError'>, OperationalError('table learning_sessions has no column named vocab_practiced'), <traceback object at 0x0000028DC3FCCD40>)
---
Traceback (most recent call last):
  File "C:\Users\nolan\personal\personal-projects\Nabu\core\session_manager.py", line 332, in _save_session_to_db
    self.db.insert('learning_sessions', data)
  File "C:\Users\nolan\personal\personal-projects\Nabu\data\database.py", line 154, in insert
    cursor = conn.execute(query, tuple(sanitized_data.values()))
sqlite3.OperationalError: table learning_sessions has no column named vocab_practiced
2025-08-23 19:51:55,771 - data.database - ERROR - database:get_connection:66
Message: Database operation failed: no such column: vocab_practiced
Exception: (<class 'sqlite3.OperationalError'>, OperationalError('no such column: vocab_practiced'), <traceback object at 0x0000028DC87BBB00>)
---
Traceback (most recent call last):
  File "C:\Users\nolan\personal\personal-projects\Nabu\data\database.py", line 62, in get_connection
    yield conn
  File "C:\Users\nolan\personal\personal-projects\Nabu\data\database.py", line 165, in update
    cursor = conn.execute(query, tuple(sanitized_data.values()) + where_params)
sqlite3.OperationalError: no such column: vocab_practiced
2025-08-23 19:51:55,774 - core.session_manager - ERROR - session_manager:_update_session_in_db:354
Message: Failed to update session in database: no such column: vocab_practiced
Exception: (<class 'sqlite3.OperationalError'>, OperationalError('no such column: vocab_practiced'), <traceback object at 0x0000028DC825E800>)
---
Traceback (most recent call last):
  File "C:\Users\nolan\personal\personal-projects\Nabu\core\session_manager.py", line 351, in _update_session_in_db
    self.db.update('learning_sessions', data, 'id = ?', (session.session_id,))
  File "C:\Users\nolan\personal\personal-projects\Nabu\data\database.py", line 165, in update
    cursor = conn.execute(query, tuple(sanitized_data.values()) + where_params)
sqlite3.OperationalError: no such column: vocab_practiced
2025-08-23 19:51:55,777 - core.session_manager - ERROR - session_manager:_generate_session_notes:439
Message: Error generating session notes: name 'config' is not defined
Exception: None
---

2025-08-23 20:02:44,883 - __main__ - ERROR - main:main:68
Message: Application crashed: 'TabManager' object has no attribute 'nav_buttons'
Exception: (<class 'AttributeError'>, AttributeError("'TabManager' object has no attribute 'nav_buttons'"), <traceback object at 0x0000022BC74BBD40>)
---
Traceback (most recent call last):
  File "C:\Users\nolan\personal\personal-projects\Nabu\main.py", line 59, in main
    app = TutorApplication()
  File "C:\Users\nolan\personal\personal-projects\Nabu\core\application.py", line 45, in __init__
    self._initialize_ui()
  File "C:\Users\nolan\personal\personal-projects\Nabu\core\application.py", line 85, in _initialize_ui
    self.tab_manager = TabManager(
  File "C:\Users\nolan\personal\personal-projects\Nabu\ui\tab_manager.py", line 41, in __init__
    self._create_tabs()
  File "C:\Users\nolan\personal\personal-projects\Nabu\ui\tab_manager.py", line 106, in _create_tabs
    self._show_tab('home')
  File "C:\Users\nolan\personal\personal-projects\Nabu\ui\tab_manager.py", line 224, in _show_tab
    for key, btn in self.nav_buttons.items():
AttributeError: 'TabManager' object has no attribute 'nav_buttons'
2025-08-23 20:04:08,646 - __main__ - ERROR - main:main:68
Message: Application crashed: 'TabManager' object has no attribute 'nav_buttons'
Exception: (<class 'AttributeError'>, AttributeError("'TabManager' object has no attribute 'nav_buttons'"), <traceback object at 0x000002AB88C7B880>)
---
Traceback (most recent call last):
  File "C:\Users\nolan\personal\personal-projects\Nabu\main.py", line 59, in main
    app = TutorApplication()
  File "C:\Users\nolan\personal\personal-projects\Nabu\core\application.py", line 45, in __init__
    self._initialize_ui()
  File "C:\Users\nolan\personal\personal-projects\Nabu\core\application.py", line 85, in _initialize_ui
    self.tab_manager = TabManager(
  File "C:\Users\nolan\personal\personal-projects\Nabu\ui\tab_manager.py", line 41, in __init__
    self._create_tabs()
  File "C:\Users\nolan\personal\personal-projects\Nabu\ui\tab_manager.py", line 106, in _create_tabs
    self._show_tab('home')
  File "C:\Users\nolan\personal\personal-projects\Nabu\ui\tab_manager.py", line 224, in _show_tab
    for key, btn in self.nav_buttons.items():
AttributeError: 'TabManager' object has no attribute 'nav_buttons'
2025-08-23 20:05:41,252 - __main__ - ERROR - main:main:68
Message: Application crashed: 'TabManager' object has no attribute 'tab_container'
Exception: (<class 'AttributeError'>, AttributeError("'TabManager' object has no attribute 'tab_container'"), <traceback object at 0x0000025CCC327500>)
---
Traceback (most recent call last):
  File "C:\Users\nolan\personal\personal-projects\Nabu\main.py", line 59, in main
    app = TutorApplication()
  File "C:\Users\nolan\personal\personal-projects\Nabu\core\application.py", line 45, in __init__
    self._initialize_ui()
  File "C:\Users\nolan\personal\personal-projects\Nabu\core\application.py", line 101, in _initialize_ui
    self.current_frame = self.tab_manager.tab_container
AttributeError: 'TabManager' object has no attribute 'tab_container'
